Workbook

Sheet HARIAN WAJIB DIISI
A1: LAPJUSIK HARIAN
A3: PEKERJAAN | D3: : PEMBANGUNAN KOPERASI MERAH PUTIH PT. AGRINAS PANGAN NUSANTARA (PERSERO)
A4: LOKASI | D4: : PROVINSI JAWA TENGAH
A5: TAHUN ANGGARAN | D5: : 2025
A7: NO | B7: URAIAN PEKERJAAN | F7: VOLUME | G7: SATUAN | H7: HARGA SATUAN | I7: JUMLAH HARGA SATUAN | J7: NILAI BOBOT (%) | K7: NOVEMBER | AO7: DESEMBER | BT7: JANUARI
K8: SAB | L8: MING | M8: SEN | N8: SEL | O8: RAB | P8: KAM | Q8: JUM | R8: SAB | S8: MING | T8: SEN | U8: SEL | V8: RAB | W8: KAM | X8: JUM | Y8: SAB | Z8: MING | AA8: SEN | AB8: SEL | AC8: RAB | AD8: KAM | AE8: JUM | AF8: SAB | AG8: MING | AH8: SEN | AI8: SEL | AJ8: RAB | AK8: KAM | AL8: JUM | AM8: SAB | AN8: MING | AO8: SEN | AP8: SEL | AQ8: RAB | AR8: KAM | AS8: JUM | AT8: SAB | AU8: MING | AV8: SEN | AW8: SEL | AX8: RAB | AY8: KAM | AZ8: JUM | BA8: SAB | BB8: MING | BC8: SEN | BD8: SEL | BE8: RAB | BF8: KAM | BG8: JUM | BH8: SAB | BI8: MING | BJ8: SEN | BK8: SEL | BL8: RAB | BM8: KAM | BN8: JUM | BO8: SAB | BP8: MING | BQ8: SEN | BR8: SEL | BS8: RAB | BT8: KAM | BU8: JUM | BV8: SAB | BW8: MING | BX8: SEN | BY8: SEL | BZ8: RAB | CA8: KAM | CB8: JUM | CC8: SAB | CD8: MING | CE8: SEN | CF8: SEL | CG8: RAB | CH8: KAM | CI8: JUM | CJ8: SAB | CK8: MING | CL8: SEN | CM8: SEL | CN8: RAB | CO8: KAM | CP8: JUM | CQ8: SAB | CR8: MING | CS8: SEN | CT8: SEL | CU8: RAB | CV8: KAM | CW8: JUM | CX8: SAB
H9: (Rp) | I9: (Rp) | K9: 1 | L9: 2 | M9: 3 | N9: 4 | O9: 5 | P9: 6 | Q9: 7 | R9: 8 | S9: 9 | T9: 10 | U9: 11 | V9: 12 | W9: 13 | X9: 14 | Y9: 15 | Z9: 16 | AA9: 17 | AB9: 18 | AC9: 19 | AD9: 20 | AE9: 21 | AF9: 22 | AG9: 23 | AH9: 24 | AI9: 25 | AJ9: 26 | AK9: 27 | AL9: 28 | AM9: 29 | AN9: 30 | AO9: 1 | AP9: 2 | AQ9: 3 | AR9: 4 | AS9: 5 | AT9: 6 | AU9: 7 | AV9: 8 | AW9: 9 | AX9: 10 | AY9: 11 | AZ9: 12 | BA9: 13 | BB9: 14 | BC9: 15 | BD9: 16 | BE9: 17 | BF9: 18 | BG9: 19 | BH9: 20 | BI9: 21 | BJ9: 22 | BK9: 23 | BL9: 24 | BM9: 25 | BN9: 26 | BO9: 27 | BP9: 28 | BQ9: 29 | BR9: 30 | BS9: 31 | BT9: 1 | BU9: 2 | BV9: 3 | BW9: 4 | BX9: 5 | BY9: 6 | BZ9: 7 | CA9: 8 | CB9: 9 | CC9: 10 | CD9: 11 | CE9: 12 | CF9: 13 | CG9: 14 | CH9: 15 | CI9: 16 | CJ9: 17 | CK9: 18 | CL9: 19 | CM9: 20 | CN9: 21 | CO9: 22 | CP9: 23 | CQ9: 24 | CR9: 25 | CS9: 26 | CT9: 27 | CU9: 28 | CV9: 29 | CW9: 30 | CX9: 31
A11: I | B11: PEKERJAAN PERSIAPAN | I11: =SUM(I12:I13) -> 21788295
A12: 1 | B12: Pengukuran dan pasang bouwplank | F12: 60.3 | G12: m' | H12: 78900 | I12: =H12*F12 -> 4757670 | J12: =I12/I$364*100 -> 0.4757659 | K12: 100
A13: 2 | B13: Pembersihan lahan awal sampai akhir pekerjaan | F13: 908.3 | G13: m² | H13: 18750 | I13: =H13*F13 -> 17030625 | J13: =I13/I$364*100 -> 1.7030586 | L13: 50 | M13: 50
A15: II | B15: PEKERJAAN STRUKTUR
B16: II.1 Pekerjaan Struktur Bawah | I16: =SUM(I17:I65) -> 1.6194539e+08
A17: 1 | B17: Pekerjaan galian tanah pondasi footplat | F17: 70.78 | G17: m³ | H17: 70180 | I17: =H17*F17 -> 4967340.4 | J17: =I17/I$364*100 -> 0.49673289 | L17: 100
A18: 2 | B18: Pekerjaan urugan tanah kembali pondasi footplat | F18: 18.594 | G18: m³ | H18: 46750 | I18: =H18*F18 -> 869269.5 | J18: =I18/I$364*100 -> 0.08692675 | M18: 100
A19: 3 | B19: Pekerjaan lantai kerja bawah pondasi footplat | F19: 2.32425 | G19: m³ | H19: 735328 | I19: =H19*F19 -> 1709086.1 | J19: =I19/I$364*100 -> 0.17090822 | N19: 100
A20: 4 | B20: Pekerjaan galian tanah pondasi batu belah | F20: 19.8 | G20: m³ | H20: 70180 | I20: =H20*F20 -> 1389564 | J20: =I20/I$364*100 -> 0.13895608 | O20: 100
A21: 5 | B21: Pekerjaan lantai kerja bawah pondasi batu belah | F21: 4.65 | G21: m³ | H21: 735328 | I21: =H21*F21 -> 3419275.2 | J21: =I21/I$364*100 -> 0.34192673 | O21: 100
A22: 6 | B22: Pekerjaan pondasi batu belah | F22: 27.9 | G22: m³ | H22: 654079.58 | I22: =H22*F22 -> 18248820 | J22: =I22/I$364*100 -> 1.8248778 | P22: 50 | Q22: 50
A23: 7 | B23: Pekerjaan urugan tanah peninggian lantai termasuk pemadatan tanah | F23: 256 | G23: m³ | H23: 65802 | I23: =H23*F23 -> 16845312 | J23: =I23/I$364*100 -> 1.6845273 | R23: 50 | S23: 50
A24: 8 | B24: Pekerjaan pondasi footplat tipe F1a
B25: - Pekerjaan beton K-225 | F25: 5.76 | G25: m³ | H25: 772596 | I25: =H25*F25 -> 4450153 | J25: =I25/I$364*100 -> 0.44501427
B26: - Pekerjaan bekisting pondasi | F26: 7 | G26: m² | H26: 87929.63 | I26: =H26*F26 -> 615507.41 | J26: =I26/I$364*100 -> 0.061550599
B27: - Pekerjaan pembesian ulir | F27: 180.52116 | G27: kg | H27: 12818.52 | I27: =H27*F27 -> 2314014.1 | J27: =I27/I$364*100 -> 0.23140088
B28: - Pekerjaan pembesian polos | F28: 90.016497 | G28: kg | H28: 11876.74 | I28: =H28*F28 -> 1069102.5 | J28: =I28/I$364*100 -> 0.10691001
A29: 9 | B29: Pekerjaan pondasi footplat tipe F1b
B30: - Pekerjaan beton K-225 | F30: 4.55 | G30: m³ | H30: =H25 -> 772596 | I30: =H30*F30 -> 3515311.8 | J30: =I30/I$364*100 -> 0.35153037
B31: - Pekerjaan bekisting pondasi | F31: 9 | G31: m² | H31: =H26 -> 87929.63 | I31: =H31*F31 -> 791366.67 | J31: =I31/I$364*100 -> 0.079136485
B32: - Pekerjaan pembesian ulir | F32: 232.09864 | G32: kg | H32: =H27 -> 12818.52 | I32: =H32*F32 -> 2975161 | J32: =I32/I$364*100 -> 0.29751542
B33: - Pekerjaan pembesian polos | F33: 121.03838 | G33: kg | H33: =H28 -> 11876.74 | I33: =H33*F33 -> 1437541.4 | J33: =I33/I$364*100 -> 0.14375381
A34: 10 | B34: Pekerjaan pondasi footplat tipe F1c
B35: - Pekerjaan beton K-225 | F35: 0.78875 | G35: m³ | H35: =H30 -> 772596 | I35: =H35*F35 -> 609385.1 | J35: =I35/I$364*100 -> 0.060938369
B36: - Pekerjaan bekisting pondasi | F36: 2 | G36: m² | H36: =H31 -> 87929.63 | I36: =H36*F36 -> 175859.26 | J36: =I36/I$364*100 -> 0.017585885
B37: - Pekerjaan pembesian ulir | F37: 51.577475 | G37: kg | H37: =H32 -> 12818.52 | I37: =H37*F37 -> 661146.9 | J37: =I37/I$364*100 -> 0.066114537
B38: - Pekerjaan pembesian polos | F38: 26.897418 | G38: kg | H38: =H33 -> 11876.74 | I38: =H38*F38 -> 319453.64 | J38: =I38/I$364*100 -> 0.031945291
A39: 11 | B39: Pekerjaan pondasi footplat tipe F2
B40: - Pekerjaan beton K-225 | F40: 1.512 | G40: m³ | H40: =H35 -> 772596 | I40: =H40*F40 -> 1168165.2 | J40: =I40/I$364*100 -> 0.11681625
B41: - Pekerjaan bekisting pondasi | F41: 4.8 | G41: m² | H41: =H36 -> 87929.63 | I41: =H41*F41 -> 422062.22 | J41: =I41/I$364*100 -> 0.042206125
B42: - Pekerjaan pembesian ulir | F42: 103.13828 | G42: kg | H42: =H37 -> 12818.52 | I42: =H42*F42 -> 1322080.1 | J42: =I42/I$364*100 -> 0.13220771
B43: - Pekerjaan pembesian polos | F43: 51.835715 | G43: kg | H43: =H38 -> 11876.74 | I43: =H43*F43 -> 615639.3 | J43: =I43/I$364*100 -> 0.061563789
A44: 12 | B44: Pekerjaan kolom pedestal tipe K1a ukuran 25 x 30 cm
...

Sheet HARIAN KOMULATIF
A1: LAPJUSIK HARIAN
A3: PEKERJAAN | D3: : PEMBANGUNAN KOPERASI MERAH PUTIH PT. AGRINAS PANGAN NUSANTARA (PERSERO)
A4: LOKASI | D4: : PROVINSI JAWA TENGAH
A5: TAHUN ANGGARAN | D5: : 2025
A7: NO | B7: URAIAN PEKERJAAN | F7: VOLUME | G7: SATUAN | H7: HARGA SATUAN | I7: JUMLAH HARGA SATUAN | J7: NILAI BOBOT (%) | K7: NOVEMBER | AO7: DESEMBER | BT7: JANUARI
K8: SAB | L8: MING | M8: SEN | N8: SEL | O8: RAB | P8: KAM | Q8: JUM | R8: SAB | S8: MING | T8: SEN | U8: SEL | V8: RAB | W8: KAM | X8: JUM | Y8: SAB | Z8: MING | AA8: SEN | AB8: SEL | AC8: RAB | AD8: KAM | AE8: JUM | AF8: SAB | AG8: MING | AH8: SEN | AI8: SEL | AJ8: RAB | AK8: KAM | AL8: JUM | AM8: SAB | AN8: MING | AO8: SEN | AP8: SEL | AQ8: RAB | AR8: KAM | AS8: JUM | AT8: SAB | AU8: MING | AV8: SEN | AW8: SEL | AX8: RAB | AY8: KAM | AZ8: JUM | BA8: SAB | BB8: MING | BC8: SEN | BD8: SEL | BE8: RAB | BF8: KAM | BG8: JUM | BH8: SAB | BI8: MING | BJ8: SEN | BK8: SEL | BL8: RAB | BM8: KAM | BN8: JUM | BO8: SAB | BP8: MING | BQ8: SEN | BR8: SEL | BS8: RAB | BT8: KAM | BU8: JUM | BV8: SAB | BW8: MING | BX8: SEN | BY8: SEL | BZ8: RAB | CA8: KAM | CB8: JUM | CC8: SAB | CD8: MING | CE8: SEN | CF8: SEL | CG8: RAB | CH8: KAM | CI8: JUM | CJ8: SAB | CK8: MING | CL8: SEN | CM8: SEL | CN8: RAB | CO8: KAM | CP8: JUM | CQ8: SAB | CR8: MING | CS8: SEN | CT8: SEL | CU8: RAB | CV8: KAM | CW8: JUM | CX8: SAB
H9: (Rp) | I9: (Rp) | K9: 1 | L9: 2 | M9: 3 | N9: 4 | O9: 5 | P9: 6 | Q9: 7 | R9: 8 | S9: 9 | T9: 10 | U9: 11 | V9: 12 | W9: 13 | X9: 14 | Y9: 15 | Z9: 16 | AA9: 17 | AB9: 18 | AC9: 19 | AD9: 20 | AE9: 21 | AF9: 22 | AG9: 23 | AH9: 24 | AI9: 25 | AJ9: 26 | AK9: 27 | AL9: 28 | AM9: 29 | AN9: 30 | AO9: 1 | AP9: 2 | AQ9: 3 | AR9: 4 | AS9: 5 | AT9: 6 | AU9: 7 | AV9: 8 | AW9: 9 | AX9: 10 | AY9: 11 | AZ9: 12 | BA9: 13 | BB9: 14 | BC9: 15 | BD9: 16 | BE9: 17 | BF9: 18 | BG9: 19 | BH9: 20 | BI9: 21 | BJ9: 22 | BK9: 23 | BL9: 24 | BM9: 25 | BN9: 26 | BO9: 27 | BP9: 28 | BQ9: 29 | BR9: 30 | BS9: 31 | BT9: 1 | BU9: 2 | BV9: 3 | BW9: 4 | BX9: 5 | BY9: 6 | BZ9: 7 | CA9: 8 | CB9: 9 | CC9: 10 | CD9: 11 | CE9: 12 | CF9: 13 | CG9: 14 | CH9: 15 | CI9: 16 | CJ9: 17 | CK9: 18 | CL9: 19 | CM9: 20 | CN9: 21 | CO9: 22 | CP9: 23 | CQ9: 24 | CR9: 25 | CS9: 26 | CT9: 27 | CU9: 28 | CV9: 29 | CW9: 30 | CX9: 31
A11: I | B11: PEKERJAAN PERSIAPAN | I11: =SUM(I12:I13) -> 21788295
A12: 1 | B12: Pengukuran dan pasang bouwplank | F12: 60.3 | G12: m' | H12: 78900 | I12: =H12*F12 -> 4757670 | J12: =I12/I$364*100 -> 0.4757659 | K12: ='HARIAN WAJIB DIISI'!K12 -> 100 | L12: =K12+'HARIAN WAJIB DIISI'!L12 -> 100 | M12: =L12+'HARIAN WAJIB DIISI'!M12 -> 100 | N12: =M12+'HARIAN WAJIB DIISI'!N12 -> 100 | O12: =N12+'HARIAN WAJIB DIISI'!O12 -> 100 | P12: =O12+'HARIAN WAJIB DIISI'!P12 -> 100 | Q12: =P12+'HARIAN WAJIB DIISI'!Q12 -> 100 | R12: =Q12+'HARIAN WAJIB DIISI'!R12 -> 100 | S12: =R12+'HARIAN WAJIB DIISI'!S12 -> 100 | ... CX12: =CW12+'HARIAN WAJIB DIISI'!CX12 -> 100
A13: 2 | B13: Pembersihan lahan awal sampai akhir pekerjaan | F13: 908.3 | G13: m² | H13: 18750 | I13: =H13*F13 -> 17030625 | J13: =I13/I$364*100 -> 1.7030586 | K13: ='HARIAN WAJIB DIISI'!K13 -> 0 | L13: =K13+'HARIAN WAJIB DIISI'!L13 -> 50 | M13: =L13+'HARIAN WAJIB DIISI'!M13 -> 100 | N13: =M13+'HARIAN WAJIB DIISI'!N13 -> 100 | O13: =N13+'HARIAN WAJIB DIISI'!O13 -> 100 | P13: =O13+'HARIAN WAJIB DIISI'!P13 -> 100 | Q13: =P13+'HARIAN WAJIB DIISI'!Q13 -> 100 | R13: =Q13+'HARIAN WAJIB DIISI'!R13 -> 100 | S13: =R13+'HARIAN WAJIB DIISI'!S13 -> 100 | ... CX13: =CW13+'HARIAN WAJIB DIISI'!CX13 -> 100
K14: ='HARIAN WAJIB DIISI'!K14 -> 0 | L14: =K14+'HARIAN WAJIB DIISI'!L14 -> 0 | M14: =L14+'HARIAN WAJIB DIISI'!M14 -> 0 | N14: =M14+'HARIAN WAJIB DIISI'!N14 -> 0 | O14: =N14+'HARIAN WAJIB DIISI'!O14 -> 0 | P14: =O14+'HARIAN WAJIB DIISI'!P14 -> 0 | Q14: =P14+'HARIAN WAJIB DIISI'!Q14 -> 0 | R14: =Q14+'HARIAN WAJIB DIISI'!R14 -> 0 | S14: =R14+'HARIAN WAJIB DIISI'!S14 -> 0 | ... CX14: =CW14+'HARIAN WAJIB DIISI'!CX14 -> 0
A15: II | B15: PEKERJAAN STRUKTUR | K15: ='HARIAN WAJIB DIISI'!K15 -> 0 | L15: =K15+'HARIAN WAJIB DIISI'!L15 -> 0 | M15: =L15+'HARIAN WAJIB DIISI'!M15 -> 0 | N15: =M15+'HARIAN WAJIB DIISI'!N15 -> 0 | O15: =N15+'HARIAN WAJIB DIISI'!O15 -> 0 | P15: =O15+'HARIAN WAJIB DIISI'!P15 -> 0 | Q15: =P15+'HARIAN WAJIB DIISI'!Q15 -> 0 | R15: =Q15+'HARIAN WAJIB DIISI'!R15 -> 0 | S15: =R15+'HARIAN WAJIB DIISI'!S15 -> 0 | ... CX15: =CW15+'HARIAN WAJIB DIISI'!CX15 -> 0
B16: II.1 Pekerjaan Struktur Bawah | I16: =SUM(I17:I65) -> 1.6194539e+08 | K16: ='HARIAN WAJIB DIISI'!K16 -> 0 | L16: =K16+'HARIAN WAJIB DIISI'!L16 -> 0 | M16: =L16+'HARIAN WAJIB DIISI'!M16 -> 0 | N16: =M16+'HARIAN WAJIB DIISI'!N16 -> 0 | O16: =N16+'HARIAN WAJIB DIISI'!O16 -> 0 | P16: =O16+'HARIAN WAJIB DIISI'!P16 -> 0 | Q16: =P16+'HARIAN WAJIB DIISI'!Q16 -> 0 | R16: =Q16+'HARIAN WAJIB DIISI'!R16 -> 0 | S16: =R16+'HARIAN WAJIB DIISI'!S16 -> 0 | ... CX16: =CW16+'HARIAN WAJIB DIISI'!CX16 -> 0
A17: 1 | B17: Pekerjaan galian tanah pondasi footplat | F17: 70.78 | G17: m³ | H17: 70180 | I17: =H17*F17 -> 4967340.4 | J17: =I17/I$364*100 -> 0.49673289 | K17: ='HARIAN WAJIB DIISI'!K17 -> 0 | L17: =K17+'HARIAN WAJIB DIISI'!L17 -> 100 | M17: =L17+'HARIAN WAJIB DIISI'!M17 -> 100 | N17: =M17+'HARIAN WAJIB DIISI'!N17 -> 100 | O17: =N17+'HARIAN WAJIB DIISI'!O17 -> 100 | P17: =O17+'HARIAN WAJIB DIISI'!P17 -> 100 | Q17: =P17+'HARIAN WAJIB DIISI'!Q17 -> 100 | R17: =Q17+'HARIAN WAJIB DIISI'!R17 -> 100 | S17: =R17+'HARIAN WAJIB DIISI'!S17 -> 100 | ... CX17: =CW17+'HARIAN WAJIB DIISI'!CX17 -> 100
A18: 2 | B18: Pekerjaan urugan tanah kembali pondasi footplat | F18: 18.594 | G18: m³ | H18: 46750 | I18: =H18*F18 -> 869269.5 | J18: =I18/I$364*100 -> 0.08692675 | K18: ='HARIAN WAJIB DIISI'!K18 -> 0 | L18: =K18+'HARIAN WAJIB DIISI'!L18 -> 0 | M18: =L18+'HARIAN WAJIB DIISI'!M18 -> 100 | N18: =M18+'HARIAN WAJIB DIISI'!N18 -> 100 | O18: =N18+'HARIAN WAJIB DIISI'!O18 -> 100 | P18: =O18+'HARIAN WAJIB DIISI'!P18 -> 100 | Q18: =P18+'HARIAN WAJIB DIISI'!Q18 -> 100 | R18: =Q18+'HARIAN WAJIB DIISI'!R18 -> 100 | S18: =R18+'HARIAN WAJIB DIISI'!S18 -> 100 | ... CX18: =CW18+'HARIAN WAJIB DIISI'!CX18 -> 100
A19: 3 | B19: Pekerjaan lantai kerja bawah pondasi footplat | F19: 2.32425 | G19: m³ | H19: 735328 | I19: =H19*F19 -> 1709086.1 | J19: =I19/I$364*100 -> 0.17090822 | K19: ='HARIAN WAJIB DIISI'!K19 -> 0 | L19: =K19+'HARIAN WAJIB DIISI'!L19 -> 0 | M19: =L19+'HARIAN WAJIB DIISI'!M19 -> 0 | N19: =M19+'HARIAN WAJIB DIISI'!N19 -> 100 | O19: =N19+'HARIAN WAJIB DIISI'!O19 -> 100 | P19: =O19+'HARIAN WAJIB DIISI'!P19 -> 100 | Q19: =P19+'HARIAN WAJIB DIISI'!Q19 -> 100 | R19: =Q19+'HARIAN WAJIB DIISI'!R19 -> 100 | S19: =R19+'HARIAN WAJIB DIISI'!S19 -> 100 | ... CX19: =CW19+'HARIAN WAJIB DIISI'!CX19 -> 100
A20: 4 | B20: Pekerjaan galian tanah pondasi batu belah | F20: 19.8 | G20: m³ | H20: 70180 | I20: =H20*F20 -> 1389564 | J20: =I20/I$364*100 -> 0.13895608 | K20: ='HARIAN WAJIB DIISI'!K20 -> 0 | L20: =K20+'HARIAN WAJIB DIISI'!L20 -> 0 | M20: =L20+'HARIAN WAJIB DIISI'!M20 -> 0 | N20: =M20+'HARIAN WAJIB DIISI'!N20 -> 0 | O20: =N20+'HARIAN WAJIB DIISI'!O20 -> 100 | P20: =O20+'HARIAN WAJIB DIISI'!P20 -> 100 | Q20: =P20+'HARIAN WAJIB DIISI'!Q20 -> 100 | R20: =Q20+'HARIAN WAJIB DIISI'!R20 -> 100 | S20: =R20+'HARIAN WAJIB DIISI'!S20 -> 100 | ... CX20: =CW20+'HARIAN WAJIB DIISI'!CX20 -> 100
A21: 5 | B21: Pekerjaan lantai kerja bawah pondasi batu belah | F21: 4.65 | G21: m³ | H21: 735328 | I21: =H21*F21 -> 3419275.2 | J21: =I21/I$364*100 -> 0.34192673 | K21: ='HARIAN WAJIB DIISI'!K21 -> 0 | L21: =K21+'HARIAN WAJIB DIISI'!L21 -> 0 | M21: =L21+'HARIAN WAJIB DIISI'!M21 -> 0 | N21: =M21+'HARIAN WAJIB DIISI'!N21 -> 0 | O21: =N21+'HARIAN WAJIB DIISI'!O21 -> 100 | P21: =O21+'HARIAN WAJIB DIISI'!P21 -> 100 | Q21: =P21+'HARIAN WAJIB DIISI'!Q21 -> 100 | R21: =Q21+'HARIAN WAJIB DIISI'!R21 -> 100 | S21: =R21+'HARIAN WAJIB DIISI'!S21 -> 100 | ... CX21: =CW21+'HARIAN WAJIB DIISI'!CX21 -> 100
A22: 6 | B22: Pekerjaan pondasi batu belah | F22: 27.9 | G22: m³ | H22: 654079.58 | I22: =H22*F22 -> 18248820 | J22: =I22/I$364*100 -> 1.8248778 | K22: ='HARIAN WAJIB DIISI'!K22 -> 0 | L22: =K22+'HARIAN WAJIB DIISI'!L22 -> 0 | M22: =L22+'HARIAN WAJIB DIISI'!M22 -> 0 | N22: =M22+'HARIAN WAJIB DIISI'!N22 -> 0 | O22: =N22+'HARIAN WAJIB DIISI'!O22 -> 0 | P22: =O22+'HARIAN WAJIB DIISI'!P22 -> 50 | Q22: =P22+'HARIAN WAJIB DIISI'!Q22 -> 100 | R22: =Q22+'HARIAN WAJIB DIISI'!R22 -> 100 | S22: =R22+'HARIAN WAJIB DIISI'!S22 -> 100 | ... CX22: =CW22+'HARIAN WAJIB DIISI'!CX22 -> 100
A23: 7 | B23: Pekerjaan urugan tanah peninggian lantai termasuk pemadatan tanah | F23: 256 | G23: m³ | H23: 65802 | I23: =H23*F23 -> 16845312 | J23: =I23/I$364*100 -> 1.6845273 | K23: ='HARIAN WAJIB DIISI'!K23 -> 0 | L23: =K23+'HARIAN WAJIB DIISI'!L23 -> 0 | M23: =L23+'HARIAN WAJIB DIISI'!M23 -> 0 | N23: =M23+'HARIAN WAJIB DIISI'!N23 -> 0 | O23: =N23+'HARIAN WAJIB DIISI'!O23 -> 0 | P23: =O23+'HARIAN WAJIB DIISI'!P23 -> 0 | Q23: =P23+'HARIAN WAJIB DIISI'!Q23 -> 0 | R23: =Q23+'HARIAN WAJIB DIISI'!R23 -> 50 | S23: =R23+'HARIAN WAJIB DIISI'!S23 -> 100 | ... CX23: =CW23+'HARIAN WAJIB DIISI'!CX23 -> 100
A24: 8 | B24: Pekerjaan pondasi footplat tipe F1a | K24: ='HARIAN WAJIB DIISI'!K24 -> 0 | L24: =K24+'HARIAN WAJIB DIISI'!L24 -> 0 | M24: =L24+'HARIAN WAJIB DIISI'!M24 -> 0 | N24: =M24+'HARIAN WAJIB DIISI'!N24 -> 0 | O24: =N24+'HARIAN WAJIB DIISI'!O24 -> 0 | P24: =O24+'HARIAN WAJIB DIISI'!P24 -> 0 | Q24: =P24+'HARIAN WAJIB DIISI'!Q24 -> 0 | R24: =Q24+'HARIAN WAJIB DIISI'!R24 -> 0 | S24: =R24+'HARIAN WAJIB DIISI'!S24 -> 0 | ... CX24: =CW24+'HARIAN WAJIB DIISI'!CX24 -> 0
B25: - Pekerjaan beton K-225 | F25: 5.76 | G25: m³ | H25: 772596 | I25: =H25*F25 -> 4450153 | J25: =I25/I$364*100 -> 0.44501427 | K25: ='HARIAN WAJIB DIISI'!K25 -> 0 | L25: =K25+'HARIAN WAJIB DIISI'!L25 -> 0 | M25: =L25+'HARIAN WAJIB DIISI'!M25 -> 0 | N25: =M25+'HARIAN WAJIB DIISI'!N25 -> 0 | O25: =N25+'HARIAN WAJIB DIISI'!O25 -> 0 | P25: =O25+'HARIAN WAJIB DIISI'!P25 -> 0 | Q25: =P25+'HARIAN WAJIB DIISI'!Q25 -> 0 | R25: =Q25+'HARIAN WAJIB DIISI'!R25 -> 0 | S25: =R25+'HARIAN WAJIB DIISI'!S25 -> 0 | ... CX25: =CW25+'HARIAN WAJIB DIISI'!CX25 -> 0
B26: - Pekerjaan bekisting pondasi | F26: 7 | G26: m² | H26: 87929.63 | I26: =H26*F26 -> 615507.41 | J26: =I26/I$364*100 -> 0.061550599 | K26: ='HARIAN WAJIB DIISI'!K26 -> 0 | L26: =K26+'HARIAN WAJIB DIISI'!L26 -> 0 | M26: =L26+'HARIAN WAJIB DIISI'!M26 -> 0 | N26: =M26+'HARIAN WAJIB DIISI'!N26 -> 0 | O26: =N26+'HARIAN WAJIB DIISI'!O26 -> 0 | P26: =O26+'HARIAN WAJIB DIISI'!P26 -> 0 | Q26: =P26+'HARIAN WAJIB DIISI'!Q26 -> 0 | R26: =Q26+'HARIAN WAJIB DIISI'!R26 -> 0 | S26: =R26+'HARIAN WAJIB DIISI'!S26 -> 0 | ... CX26: =CW26+'HARIAN WAJIB DIISI'!CX26 -> 0
B27: - Pekerjaan pembesian ulir | F27: 180.52116 | G27: kg | H27: 12818.52 | I27: =H27*F27 -> 2314014.1 | J27: =I27/I$364*100 -> 0.23140088 | K27: ='HARIAN WAJIB DIISI'!K27 -> 0 | L27: =K27+'HARIAN WAJIB DIISI'!L27 -> 0 | M27: =L27+'HARIAN WAJIB DIISI'!M27 -> 0 | N27: =M27+'HARIAN WAJIB DIISI'!N27 -> 0 | O27: =N27+'HARIAN WAJIB DIISI'!O27 -> 0 | P27: =O27+'HARIAN WAJIB DIISI'!P27 -> 0 | Q27: =P27+'HARIAN WAJIB DIISI'!Q27 -> 0 | R27: =Q27+'HARIAN WAJIB DIISI'!R27 -> 0 | S27: =R27+'HARIAN WAJIB DIISI'!S27 -> 0 | ... CX27: =CW27+'HARIAN WAJIB DIISI'!CX27 -> 0
B28: - Pekerjaan pembesian polos | F28: 90.016497 | G28: kg | H28: 11876.74 | I28: =H28*F28 -> 1069102.5 | J28: =I28/I$364*100 -> 0.10691001 | K28: ='HARIAN WAJIB DIISI'!K28 -> 0 | L28: =K28+'HARIAN WAJIB DIISI'!L28 -> 0 | M28: =L28+'HARIAN WAJIB DIISI'!M28 -> 0 | N28: =M28+'HARIAN WAJIB DIISI'!N28 -> 0 | O28: =N28+'HARIAN WAJIB DIISI'!O28 -> 0 | P28: =O28+'HARIAN WAJIB DIISI'!P28 -> 0 | Q28: =P28+'HARIAN WAJIB DIISI'!Q28 -> 0 | R28: =Q28+'HARIAN WAJIB DIISI'!R28 -> 0 | S28: =R28+'HARIAN WAJIB DIISI'!S28 -> 0 | ... CX28: =CW28+'HARIAN WAJIB DIISI'!CX28 -> 0
A29: 9 | B29: Pekerjaan pondasi footplat tipe F1b | K29: ='HARIAN WAJIB DIISI'!K29 -> 0 | L29: =K29+'HARIAN WAJIB DIISI'!L29 -> 0 | M29: =L29+'HARIAN WAJIB DIISI'!M29 -> 0 | N29: =M29+'HARIAN WAJIB DIISI'!N29 -> 0 | O29: =N29+'HARIAN WAJIB DIISI'!O29 -> 0 | P29: =O29+'HARIAN WAJIB DIISI'!P29 -> 0 | Q29: =P29+'HARIAN WAJIB DIISI'!Q29 -> 0 | R29: =Q29+'HARIAN WAJIB DIISI'!R29 -> 0 | S29: =R29+'HARIAN WAJIB DIISI'!S29 -> 0 | ... CX29: =CW29+'HARIAN WAJIB DIISI'!CX29 -> 0
B30: - Pekerjaan beton K-225 | F30: 4.55 | G30: m³ | H30: =H25 -> 772596 | I30: =H30*F30 -> 3515311.8 | J30: =I30/I$364*100 -> 0.35153037 | K30: ='HARIAN WAJIB DIISI'!K30 -> 0 | L30: =K30+'HARIAN WAJIB DIISI'!L30 -> 0 | M30: =L30+'HARIAN WAJIB DIISI'!M30 -> 0 | N30: =M30+'HARIAN WAJIB DIISI'!N30 -> 0 | O30: =N30+'HARIAN WAJIB DIISI'!O30 -> 0 | P30: =O30+'HARIAN WAJIB DIISI'!P30 -> 0 | Q30: =P30+'HARIAN WAJIB DIISI'!Q30 -> 0 | R30: =Q30+'HARIAN WAJIB DIISI'!R30 -> 0 | S30: =R30+'HARIAN WAJIB DIISI'!S30 -> 0 | ... CX30: =CW30+'HARIAN WAJIB DIISI'!CX30 -> 0
B31: - Pekerjaan bekisting pondasi | F31: 9 | G31: m² | H31: =H26 -> 87929.63 | I31: =H31*F31 -> 791366.67 | J31: =I31/I$364*100 -> 0.079136485 | K31: ='HARIAN WAJIB DIISI'!K31 -> 0 | L31: =K31+'HARIAN WAJIB DIISI'!L31 -> 0 | M31: =L31+'HARIAN WAJIB DIISI'!M31 -> 0 | N31: =M31+'HARIAN WAJIB DIISI'!N31 -> 0 | O31: =N31+'HARIAN WAJIB DIISI'!O31 -> 0 | P31: =O31+'HARIAN WAJIB DIISI'!P31 -> 0 | Q31: =P31+'HARIAN WAJIB DIISI'!Q31 -> 0 | R31: =Q31+'HARIAN WAJIB DIISI'!R31 -> 0 | S31: =R31+'HARIAN WAJIB DIISI'!S31 -> 0 | ... CX31: =CW31+'HARIAN WAJIB DIISI'!CX31 -> 0
B32: - Pekerjaan pembesian ulir | F32: 232.09864 | G32: kg | H32: =H27 -> 12818.52 | I32: =H32*F32 -> 2975161 | J32: =I32/I$364*100 -> 0.29751542 | K32: ='HARIAN WAJIB DIISI'!K32 -> 0 | L32: =K32+'HARIAN WAJIB DIISI'!L32 -> 0 | M32: =L32+'HARIAN WAJIB DIISI'!M32 -> 0 | N32: =M32+'HARIAN WAJIB DIISI'!N32 -> 0 | O32: =N32+'HARIAN WAJIB DIISI'!O32 -> 0 | P32: =O32+'HARIAN WAJIB DIISI'!P32 -> 0 | Q32: =P32+'HARIAN WAJIB DIISI'!Q32 -> 0 | R32: =Q32+'HARIAN WAJIB DIISI'!R32 -> 0 | S32: =R32+'HARIAN WAJIB DIISI'!S32 -> 0 | ... CX32: =CW32+'HARIAN WAJIB DIISI'!CX32 -> 0
B33: - Pekerjaan pembesian polos | F33: 121.03838 | G33: kg | H33: =H28 -> 11876.74 | I33: =H33*F33 -> 1437541.4 | J33: =I33/I$364*100 -> 0.14375381 | K33: ='HARIAN WAJIB DIISI'!K33 -> 0 | L33: =K33+'HARIAN WAJIB DIISI'!L33 -> 0 | M33: =L33+'HARIAN WAJIB DIISI'!M33 -> 0 | N33: =M33+'HARIAN WAJIB DIISI'!N33 -> 0 | O33: =N33+'HARIAN WAJIB DIISI'!O33 -> 0 | P33: =O33+'HARIAN WAJIB DIISI'!P33 -> 0 | Q33: =P33+'HARIAN WAJIB DIISI'!Q33 -> 0 | R33: =Q33+'HARIAN WAJIB DIISI'!R33 -> 0 | S33: =R33+'HARIAN WAJIB DIISI'!S33 -> 0 | ... CX33: =CW33+'HARIAN WAJIB DIISI'!CX33 -> 0
A34: 10 | B34: Pekerjaan pondasi footplat tipe F1c | K34: ='HARIAN WAJIB DIISI'!K34 -> 0 | L34: =K34+'HARIAN WAJIB DIISI'!L34 -> 0 | M34: =L34+'HARIAN WAJIB DIISI'!M34 -> 0 | N34: =M34+'HARIAN WAJIB DIISI'!N34 -> 0 | O34: =N34+'HARIAN WAJIB DIISI'!O34 -> 0 | P34: =O34+'HARIAN WAJIB DIISI'!P34 -> 0 | Q34: =P34+'HARIAN WAJIB DIISI'!Q34 -> 0 | R34: =Q34+'HARIAN WAJIB DIISI'!R34 -> 0 | S34: =R34+'HARIAN WAJIB DIISI'!S34 -> 0 | ... CX34: =CW34+'HARIAN WAJIB DIISI'!CX34 -> 0
B35: - Pekerjaan beton K-225 | F35: 0.78875 | G35: m³ | H35: =H30 -> 772596 | I35: =H35*F35 -> 609385.1 | J35: =I35/I$364*100 -> 0.060938369 | K35: ='HARIAN WAJIB DIISI'!K35 -> 0 | L35: =K35+'HARIAN WAJIB DIISI'!L35 -> 0 | M35: =L35+'HARIAN WAJIB DIISI'!M35 -> 0 | N35: =M35+'HARIAN WAJIB DIISI'!N35 -> 0 | O35: =N35+'HARIAN WAJIB DIISI'!O35 -> 0 | P35: =O35+'HARIAN WAJIB DIISI'!P35 -> 0 | Q35: =P35+'HARIAN WAJIB DIISI'!Q35 -> 0 | R35: =Q35+'HARIAN WAJIB DIISI'!R35 -> 0 | S35: =R35+'HARIAN WAJIB DIISI'!S35 -> 0 | ... CX35: =CW35+'HARIAN WAJIB DIISI'!CX35 -> 0
B36: - Pekerjaan bekisting pondasi | F36: 2 | G36: m² | H36: =H31 -> 87929.63 | I36: =H36*F36 -> 175859.26 | J36: =I36/I$364*100 -> 0.017585885 | K36: ='HARIAN WAJIB DIISI'!K36 -> 0 | L36: =K36+'HARIAN WAJIB DIISI'!L36 -> 0 | M36: =L36+'HARIAN WAJIB DIISI'!M36 -> 0 | N36: =M36+'HARIAN WAJIB DIISI'!N36 -> 0 | O36: =N36+'HARIAN WAJIB DIISI'!O36 -> 0 | P36: =O36+'HARIAN WAJIB DIISI'!P36 -> 0 | Q36: =P36+'HARIAN WAJIB DIISI'!Q36 -> 0 | R36: =Q36+'HARIAN WAJIB DIISI'!R36 -> 0 | S36: =R36+'HARIAN WAJIB DIISI'!S36 -> 0 | ... CX36: =CW36+'HARIAN WAJIB DIISI'!CX36 -> 0
B37: - Pekerjaan pembesian ulir | F37: 51.577475 | G37: kg | H37: =H32 -> 12818.52 | I37: =H37*F37 -> 661146.9 | J37: =I37/I$364*100 -> 0.066114537 | K37: ='HARIAN WAJIB DIISI'!K37 -> 0 | L37: =K37+'HARIAN WAJIB DIISI'!L37 -> 0 | M37: =L37+'HARIAN WAJIB DIISI'!M37 -> 0 | N37: =M37+'HARIAN WAJIB DIISI'!N37 -> 0 | O37: =N37+'HARIAN WAJIB DIISI'!O37 -> 0 | P37: =O37+'HARIAN WAJIB DIISI'!P37 -> 0 | Q37: =P37+'HARIAN WAJIB DIISI'!Q37 -> 0 | R37: =Q37+'HARIAN WAJIB DIISI'!R37 -> 0 | S37: =R37+'HARIAN WAJIB DIISI'!S37 -> 0 | ... CX37: =CW37+'HARIAN WAJIB DIISI'!CX37 -> 0
B38: - Pekerjaan pembesian polos | F38: 26.897418 | G38: kg | H38: =H33 -> 11876.74 | I38: =H38*F38 -> 319453.64 | J38: =I38/I$364*100 -> 0.031945291 | K38: ='HARIAN WAJIB DIISI'!K38 -> 0 | L38: =K38+'HARIAN WAJIB DIISI'!L38 -> 0 | M38: =L38+'HARIAN WAJIB DIISI'!M38 -> 0 | N38: =M38+'HARIAN WAJIB DIISI'!N38 -> 0 | O38: =N38+'HARIAN WAJIB DIISI'!O38 -> 0 | P38: =O38+'HARIAN WAJIB DIISI'!P38 -> 0 | Q38: =P38+'HARIAN WAJIB DIISI'!Q38 -> 0 | R38: =Q38+'HARIAN WAJIB DIISI'!R38 -> 0 | S38: =R38+'HARIAN WAJIB DIISI'!S38 -> 0 | ... CX38: =CW38+'HARIAN WAJIB DIISI'!CX38 -> 0
A39: 11 | B39: Pekerjaan pondasi footplat tipe F2 | K39: ='HARIAN WAJIB DIISI'!K39 -> 0 | L39: =K39+'HARIAN WAJIB DIISI'!L39 -> 0 | M39: =L39+'HARIAN WAJIB DIISI'!M39 -> 0 | N39: =M39+'HARIAN WAJIB DIISI'!N39 -> 0 | O39: =N39+'HARIAN WAJIB DIISI'!O39 -> 0 | P39: =O39+'HARIAN WAJIB DIISI'!P39 -> 0 | Q39: =P39+'HARIAN WAJIB DIISI'!Q39 -> 0 | R39: =Q39+'HARIAN WAJIB DIISI'!R39 -> 0 | S39: =R39+'HARIAN WAJIB DIISI'!S39 -> 0 | ... CX39: =CW39+'HARIAN WAJIB DIISI'!CX39 -> 0
B40: - Pekerjaan beton K-225 | F40: 1.512 | G40: m³ | H40: =H35 -> 772596 | I40: =H40*F40 -> 1168165.2 | J40: =I40/I$364*100 -> 0.11681625 | K40: ='HARIAN WAJIB DIISI'!K40 -> 0 | L40: =K40+'HARIAN WAJIB DIISI'!L40 -> 0 | M40: =L40+'HARIAN WAJIB DIISI'!M40 -> 0 | N40: =M40+'HARIAN WAJIB DIISI'!N40 -> 0 | O40: =N40+'HARIAN WAJIB DIISI'!O40 -> 0 | P40: =O40+'HARIAN WAJIB DIISI'!P40 -> 0 | Q40: =P40+'HARIAN WAJIB DIISI'!Q40 -> 0 | R40: =Q40+'HARIAN WAJIB DIISI'!R40 -> 0 | S40: =R40+'HARIAN WAJIB DIISI'!S40 -> 0 | ... CX40: =CW40+'HARIAN WAJIB DIISI'!CX40 -> 0
B41: - Pekerjaan bekisting pondasi | F41: 4.8 | G41: m² | H41: =H36 -> 87929.63 | I41: =H41*F41 -> 422062.22 | J41: =I41/I$364*100 -> 0.042206125 | K41: ='HARIAN WAJIB DIISI'!K41 -> 0 | L41: =K41+'HARIAN WAJIB DIISI'!L41 -> 0 | M41: =L41+'HARIAN WAJIB DIISI'!M41 -> 0 | N41: =M41+'HARIAN WAJIB DIISI'!N41 -> 0 | O41: =N41+'HARIAN WAJIB DIISI'!O41 -> 0 | P41: =O41+'HARIAN WAJIB DIISI'!P41 -> 0 | Q41: =P41+'HARIAN WAJIB DIISI'!Q41 -> 0 | R41: =Q41+'HARIAN WAJIB DIISI'!R41 -> 0 | S41: =R41+'HARIAN WAJIB DIISI'!S41 -> 0 | ... CX41: =CW41+'HARIAN WAJIB DIISI'!CX41 -> 0
B42: - Pekerjaan pembesian ulir | F42: 103.13828 | G42: kg | H42: =H37 -> 12818.52 | I42: =H42*F42 -> 1322080.1 | J42: =I42/I$364*100 -> 0.13220771 | K42: ='HARIAN WAJIB DIISI'!K42 -> 0 | L42: =K42+'HARIAN WAJIB DIISI'!L42 -> 0 | M42: =L42+'HARIAN WAJIB DIISI'!M42 -> 0 | N42: =M42+'HARIAN WAJIB DIISI'!N42 -> 0 | O42: =N42+'HARIAN WAJIB DIISI'!O42 -> 0 | P42: =O42+'HARIAN WAJIB DIISI'!P42 -> 0 | Q42: =P42+'HARIAN WAJIB DIISI'!Q42 -> 0 | R42: =Q42+'HARIAN WAJIB DIISI'!R42 -> 0 | S42: =R42+'HARIAN WAJIB DIISI'!S42 -> 0 | ... CX42: =CW42+'HARIAN WAJIB DIISI'!CX42 -> 0
B43: - Pekerjaan pembesian polos | F43: 51.835715 | G43: kg | H43: =H38 -> 11876.74 | I43: =H43*F43 -> 615639.3 | J43: =I43/I$364*100 -> 0.061563789 | K43: ='HARIAN WAJIB DIISI'!K43 -> 0 | L43: =K43+'HARIAN WAJIB DIISI'!L43 -> 0 | M43: =L43+'HARIAN WAJIB DIISI'!M43 -> 0 | N43: =M43+'HARIAN WAJIB DIISI'!N43 -> 0 | O43: =N43+'HARIAN WAJIB DIISI'!O43 -> 0 | P43: =O43+'HARIAN WAJIB DIISI'!P43 -> 0 | Q43: =P43+'HARIAN WAJIB DIISI'!Q43 -> 0 | R43: =Q43+'HARIAN WAJIB DIISI'!R43 -> 0 | S43: =R43+'HARIAN WAJIB DIISI'!S43 -> 0 | ... CX43: =CW43+'HARIAN WAJIB DIISI'!CX43 -> 0
...

Sheet PROGRES BOBOT
A1: LAPJUSIK HARIAN
A3: PEKERJAAN | D3: : PEMBANGUNAN KOPERASI MERAH PUTIH PT. AGRINAS PANGAN NUSANTARA (PERSERO)
A4: LOKASI | D4: : PROVINSI JAWA TENGAH
A5: TAHUN ANGGARAN | D5: : 2025
A7: NO | B7: URAIAN PEKERJAAN | F7: VOLUME | G7: SATUAN | H7: HARGA SATUAN | I7: JUMLAH HARGA SATUAN | J7: NILAI BOBOT (%) | K7: NOVEMBER | AO7: DESEMBER | BT7: JANUARI
K8: SAB | L8: MING | M8: SEN | N8: SEL | O8: RAB | P8: KAM | Q8: JUM | R8: SAB | S8: MING | T8: SEN | U8: SEL | V8: RAB | W8: KAM | X8: JUM | Y8: SAB | Z8: MING | AA8: SEN | AB8: SEL | AC8: RAB | AD8: KAM | AE8: JUM | AF8: SAB | AG8: MING | AH8: SEN | AI8: SEL | AJ8: RAB | AK8: KAM | AL8: JUM | AM8: SAB | AN8: MING | AO8: SEN | AP8: SEL | AQ8: RAB | AR8: KAM | AS8: JUM | AT8: SAB | AU8: MING | AV8: SEN | AW8: SEL | AX8: RAB | AY8: KAM | AZ8: JUM | BA8: SAB | BB8: MING | BC8: SEN | BD8: SEL | BE8: RAB | BF8: KAM | BG8: JUM | BH8: SAB | BI8: MING | BJ8: SEN | BK8: SEL | BL8: RAB | BM8: KAM | BN8: JUM | BO8: SAB | BP8: MING | BQ8: SEN | BR8: SEL | BS8: RAB | BT8: KAM | BU8: JUM | BV8: SAB | BW8: MING | BX8: SEN | BY8: SEL | BZ8: RAB | CA8: KAM | CB8: JUM | CC8: SAB | CD8: MING | CE8: SEN | CF8: SEL | CG8: RAB | CH8: KAM | CI8: JUM | CJ8: SAB | CK8: MING | CL8: SEN | CM8: SEL | CN8: RAB | CO8: KAM | CP8: JUM | CQ8: SAB | CR8: MING | CS8: SEN | CT8: SEL | CU8: RAB | CV8: KAM | CW8: JUM | CX8: SAB
H9: (Rp) | I9: (Rp) | K9: 1 | L9: 2 | M9: 3 | N9: 4 | O9: 5 | P9: 6 | Q9: 7 | R9: 8 | S9: 9 | T9: 10 | U9: 11 | V9: 12 | W9: 13 | X9: 14 | Y9: 15 | Z9: 16 | AA9: 17 | AB9: 18 | AC9: 19 | AD9: 20 | AE9: 21 | AF9: 22 | AG9: 23 | AH9: 24 | AI9: 25 | AJ9: 26 | AK9: 27 | AL9: 28 | AM9: 29 | AN9: 30 | AO9: 1 | AP9: 2 | AQ9: 3 | AR9: 4 | AS9: 5 | AT9: 6 | AU9: 7 | AV9: 8 | AW9: 9 | AX9: 10 | AY9: 11 | AZ9: 12 | BA9: 13 | BB9: 14 | BC9: 15 | BD9: 16 | BE9: 17 | BF9: 18 | BG9: 19 | BH9: 20 | BI9: 21 | BJ9: 22 | BK9: 23 | BL9: 24 | BM9: 25 | BN9: 26 | BO9: 27 | BP9: 28 | BQ9: 29 | BR9: 30 | BS9: 31 | BT9: 1 | BU9: 2 | BV9: 3 | BW9: 4 | BX9: 5 | BY9: 6 | BZ9: 7 | CA9: 8 | CB9: 9 | CC9: 10 | CD9: 11 | CE9: 12 | CF9: 13 | CG9: 14 | CH9: 15 | CI9: 16 | CJ9: 17 | CK9: 18 | CL9: 19 | CM9: 20 | CN9: 21 | CO9: 22 | CP9: 23 | CQ9: 24 | CR9: 25 | CS9: 26 | CT9: 27 | CU9: 28 | CV9: 29 | CW9: 30 | CX9: 31
A11: I | B11: PEKERJAAN PERSIAPAN | I11: =SUM(I12:I13) -> 21788295
A12: 1 | B12: Pengukuran dan pasang bouwplank | F12: 60.3 | G12: m' | H12: 78900 | I12: =H12*F12 -> 4757670 | J12: =I12/I$364*100 -> 0.4757659 | K12: ='HARIAN KOMULATIF'!K12/100*'PROGRES BOBOT'!$J12 -> 0.4757659 | L12: ='HARIAN KOMULATIF'!L12/100*'PROGRES BOBOT'!$J12 -> 0.4757659 | M12: ='HARIAN KOMULATIF'!M12/100*'PROGRES BOBOT'!$J12 -> 0.4757659 | N12: ='HARIAN KOMULATIF'!N12/100*'PROGRES BOBOT'!$J12 -> 0.4757659 | O12: ='HARIAN KOMULATIF'!O12/100*'PROGRES BOBOT'!$J12 -> 0.4757659 | P12: ='HARIAN KOMULATIF'!P12/100*'PROGRES BOBOT'!$J12 -> 0.4757659 | Q12: ='HARIAN KOMULATIF'!Q12/100*'PROGRES BOBOT'!$J12 -> 0.4757659 | R12: ='HARIAN KOMULATIF'!R12/100*'PROGRES BOBOT'!$J12 -> 0.4757659 | ... CX12: ='HARIAN KOMULATIF'!CX12/100*'PROGRES BOBOT'!$J12 -> 0.4757659
A13: 2 | B13: Pembersihan lahan awal sampai akhir pekerjaan | F13: 908.3 | G13: m² | H13: 18750 | I13: =H13*F13 -> 17030625 | J13: =I13/I$364*100 -> 1.7030586 | K13: ='HARIAN KOMULATIF'!K13/100*'PROGRES BOBOT'!$J13 -> 0 | L13: ='HARIAN KOMULATIF'!L13/100*'PROGRES BOBOT'!$J13 -> 0.85152929 | M13: ='HARIAN KOMULATIF'!M13/100*'PROGRES BOBOT'!$J13 -> 1.7030586 | N13: ='HARIAN KOMULATIF'!N13/100*'PROGRES BOBOT'!$J13 -> 1.7030586 | O13: ='HARIAN KOMULATIF'!O13/100*'PROGRES BOBOT'!$J13 -> 1.7030586 | P13: ='HARIAN KOMULATIF'!P13/100*'PROGRES BOBOT'!$J13 -> 1.7030586 | Q13: ='HARIAN KOMULATIF'!Q13/100*'PROGRES BOBOT'!$J13 -> 1.7030586 | R13: ='HARIAN KOMULATIF'!R13/100*'PROGRES BOBOT'!$J13 -> 1.7030586 | ... CX13: ='HARIAN KOMULATIF'!CX13/100*'PROGRES BOBOT'!$J13 -> 1.7030586
K14: ='HARIAN KOMULATIF'!K14/100*'PROGRES BOBOT'!$J14 -> 0 | L14: ='HARIAN KOMULATIF'!L14/100*'PROGRES BOBOT'!$J14 -> 0 | M14: ='HARIAN KOMULATIF'!M14/100*'PROGRES BOBOT'!$J14 -> 0 | N14: ='HARIAN KOMULATIF'!N14/100*'PROGRES BOBOT'!$J14 -> 0 | O14: ='HARIAN KOMULATIF'!O14/100*'PROGRES BOBOT'!$J14 -> 0 | P14: ='HARIAN KOMULATIF'!P14/100*'PROGRES BOBOT'!$J14 -> 0 | Q14: ='HARIAN KOMULATIF'!Q14/100*'PROGRES BOBOT'!$J14 -> 0 | R14: ='HARIAN KOMULATIF'!R14/100*'PROGRES BOBOT'!$J14 -> 0 | ... CX14: ='HARIAN KOMULATIF'!CX14/100*'PROGRES BOBOT'!$J14 -> 0
A15: II | B15: PEKERJAAN STRUKTUR | K15: ='HARIAN KOMULATIF'!K15/100*'PROGRES BOBOT'!$J15 -> 0 | L15: ='HARIAN KOMULATIF'!L15/100*'PROGRES BOBOT'!$J15 -> 0 | M15: ='HARIAN KOMULATIF'!M15/100*'PROGRES BOBOT'!$J15 -> 0 | N15: ='HARIAN KOMULATIF'!N15/100*'PROGRES BOBOT'!$J15 -> 0 | O15: ='HARIAN KOMULATIF'!O15/100*'PROGRES BOBOT'!$J15 -> 0 | P15: ='HARIAN KOMULATIF'!P15/100*'PROGRES BOBOT'!$J15 -> 0 | Q15: ='HARIAN KOMULATIF'!Q15/100*'PROGRES BOBOT'!$J15 -> 0 | R15: ='HARIAN KOMULATIF'!R15/100*'PROGRES BOBOT'!$J15 -> 0 | ... CX15: ='HARIAN KOMULATIF'!CX15/100*'PROGRES BOBOT'!$J15 -> 0
B16: II.1 Pekerjaan Struktur Bawah | I16: =SUM(I17:I65) -> 1.6194539e+08 | K16: ='HARIAN KOMULATIF'!K16/100*'PROGRES BOBOT'!$J16 -> 0 | L16: ='HARIAN KOMULATIF'!L16/100*'PROGRES BOBOT'!$J16 -> 0 | M16: ='HARIAN KOMULATIF'!M16/100*'PROGRES BOBOT'!$J16 -> 0 | N16: ='HARIAN KOMULATIF'!N16/100*'PROGRES BOBOT'!$J16 -> 0 | O16: ='HARIAN KOMULATIF'!O16/100*'PROGRES BOBOT'!$J16 -> 0 | P16: ='HARIAN KOMULATIF'!P16/100*'PROGRES BOBOT'!$J16 -> 0 | Q16: ='HARIAN KOMULATIF'!Q16/100*'PROGRES BOBOT'!$J16 -> 0 | R16: ='HARIAN KOMULATIF'!R16/100*'PROGRES BOBOT'!$J16 -> 0 | ... CX16: ='HARIAN KOMULATIF'!CX16/100*'PROGRES BOBOT'!$J16 -> 0
A17: 1 | B17: Pekerjaan galian tanah pondasi footplat | F17: 70.78 | G17: m³ | H17: 70180 | I17: =H17*F17 -> 4967340.4 | J17: =I17/I$364*100 -> 0.49673289 | K17: ='HARIAN KOMULATIF'!K17/100*'PROGRES BOBOT'!$J17 -> 0 | L17: ='HARIAN KOMULATIF'!L17/100*'PROGRES BOBOT'!$J17 -> 0.49673289 | M17: ='HARIAN KOMULATIF'!M17/100*'PROGRES BOBOT'!$J17 -> 0.49673289 | N17: ='HARIAN KOMULATIF'!N17/100*'PROGRES BOBOT'!$J17 -> 0.49673289 | O17: ='HARIAN KOMULATIF'!O17/100*'PROGRES BOBOT'!$J17 -> 0.49673289 | P17: ='HARIAN KOMULATIF'!P17/100*'PROGRES BOBOT'!$J17 -> 0.49673289 | Q17: ='HARIAN KOMULATIF'!Q17/100*'PROGRES BOBOT'!$J17 -> 0.49673289 | R17: ='HARIAN KOMULATIF'!R17/100*'PROGRES BOBOT'!$J17 -> 0.49673289 | ... CX17: ='HARIAN KOMULATIF'!CX17/100*'PROGRES BOBOT'!$J17 -> 0.49673289
A18: 2 | B18: Pekerjaan urugan tanah kembali pondasi footplat | F18: 18.594 | G18: m³ | H18: 46750 | I18: =H18*F18 -> 869269.5 | J18: =I18/I$364*100 -> 0.08692675 | K18: ='HARIAN KOMULATIF'!K18/100*'PROGRES BOBOT'!$J18 -> 0 | L18: ='HARIAN KOMULATIF'!L18/100*'PROGRES BOBOT'!$J18 -> 0 | M18: ='HARIAN KOMULATIF'!M18/100*'PROGRES BOBOT'!$J18 -> 0.08692675 | N18: ='HARIAN KOMULATIF'!N18/100*'PROGRES BOBOT'!$J18 -> 0.08692675 | O18: ='HARIAN KOMULATIF'!O18/100*'PROGRES BOBOT'!$J18 -> 0.08692675 | P18: ='HARIAN KOMULATIF'!P18/100*'PROGRES BOBOT'!$J18 -> 0.08692675 | Q18: ='HARIAN KOMULATIF'!Q18/100*'PROGRES BOBOT'!$J18 -> 0.08692675 | R18: ='HARIAN KOMULATIF'!R18/100*'PROGRES BOBOT'!$J18 -> 0.08692675 | ... CX18: ='HARIAN KOMULATIF'!CX18/100*'PROGRES BOBOT'!$J18 -> 0.08692675
A19: 3 | B19: Pekerjaan lantai kerja bawah pondasi footplat | F19: 2.32425 | G19: m³ | H19: 735328 | I19: =H19*F19 -> 1709086.1 | J19: =I19/I$364*100 -> 0.17090822 | K19: ='HARIAN KOMULATIF'!K19/100*'PROGRES BOBOT'!$J19 -> 0 | L19: ='HARIAN KOMULATIF'!L19/100*'PROGRES BOBOT'!$J19 -> 0 | M19: ='HARIAN KOMULATIF'!M19/100*'PROGRES BOBOT'!$J19 -> 0 | N19: ='HARIAN KOMULATIF'!N19/100*'PROGRES BOBOT'!$J19 -> 0.17090822 | O19: ='HARIAN KOMULATIF'!O19/100*'PROGRES BOBOT'!$J19 -> 0.17090822 | P19: ='HARIAN KOMULATIF'!P19/100*'PROGRES BOBOT'!$J19 -> 0.17090822 | Q19: ='HARIAN KOMULATIF'!Q19/100*'PROGRES BOBOT'!$J19 -> 0.17090822 | R19: ='HARIAN KOMULATIF'!R19/100*'PROGRES BOBOT'!$J19 -> 0.17090822 | ... CX19: ='HARIAN KOMULATIF'!CX19/100*'PROGRES BOBOT'!$J19 -> 0.17090822
A20: 4 | B20: Pekerjaan galian tanah pondasi batu belah | F20: 19.8 | G20: m³ | H20: 70180 | I20: =H20*F20 -> 1389564 | J20: =I20/I$364*100 -> 0.13895608 | K20: ='HARIAN KOMULATIF'!K20/100*'PROGRES BOBOT'!$J20 -> 0 | L20: ='HARIAN KOMULATIF'!L20/100*'PROGRES BOBOT'!$J20 -> 0 | M20: ='HARIAN KOMULATIF'!M20/100*'PROGRES BOBOT'!$J20 -> 0 | N20: ='HARIAN KOMULATIF'!N20/100*'PROGRES BOBOT'!$J20 -> 0 | O20: ='HARIAN KOMULATIF'!O20/100*'PROGRES BOBOT'!$J20 -> 0.13895608 | P20: ='HARIAN KOMULATIF'!P20/100*'PROGRES BOBOT'!$J20 -> 0.13895608 | Q20: ='HARIAN KOMULATIF'!Q20/100*'PROGRES BOBOT'!$J20 -> 0.13895608 | R20: ='HARIAN KOMULATIF'!R20/100*'PROGRES BOBOT'!$J20 -> 0.13895608 | ... CX20: ='HARIAN KOMULATIF'!CX20/100*'PROGRES BOBOT'!$J20 -> 0.13895608
A21: 5 | B21: Pekerjaan lantai kerja bawah pondasi batu belah | F21: 4.65 | G21: m³ | H21: 735328 | I21: =H21*F21 -> 3419275.2 | J21: =I21/I$364*100 -> 0.34192673 | K21: ='HARIAN KOMULATIF'!K21/100*'PROGRES BOBOT'!$J21 -> 0 | L21: ='HARIAN KOMULATIF'!L21/100*'PROGRES BOBOT'!$J21 -> 0 | M21: ='HARIAN KOMULATIF'!M21/100*'PROGRES BOBOT'!$J21 -> 0 | N21: ='HARIAN KOMULATIF'!N21/100*'PROGRES BOBOT'!$J21 -> 0 | O21: ='HARIAN KOMULATIF'!O21/100*'PROGRES BOBOT'!$J21 -> 0.34192673 | P21: ='HARIAN KOMULATIF'!P21/100*'PROGRES BOBOT'!$J21 -> 0.34192673 | Q21: ='HARIAN KOMULATIF'!Q21/100*'PROGRES BOBOT'!$J21 -> 0.34192673 | R21: ='HARIAN KOMULATIF'!R21/100*'PROGRES BOBOT'!$J21 -> 0.34192673 | ... CX21: ='HARIAN KOMULATIF'!CX21/100*'PROGRES BOBOT'!$J21 -> 0.34192673
A22: 6 | B22: Pekerjaan pondasi batu belah | F22: 27.9 | G22: m³ | H22: 654079.58 | I22: =H22*F22 -> 18248820 | J22: =I22/I$364*100 -> 1.8248778 | K22: ='HARIAN KOMULATIF'!K22/100*'PROGRES BOBOT'!$J22 -> 0 | L22: ='HARIAN KOMULATIF'!L22/100*'PROGRES BOBOT'!$J22 -> 0 | M22: ='HARIAN KOMULATIF'!M22/100*'PROGRES BOBOT'!$J22 -> 0 | N22: ='HARIAN KOMULATIF'!N22/100*'PROGRES BOBOT'!$J22 -> 0 | O22: ='HARIAN KOMULATIF'!O22/100*'PROGRES BOBOT'!$J22 -> 0 | P22: ='HARIAN KOMULATIF'!P22/100*'PROGRES BOBOT'!$J22 -> 0.91243891 | Q22: ='HARIAN KOMULATIF'!Q22/100*'PROGRES BOBOT'!$J22 -> 1.8248778 | R22: ='HARIAN KOMULATIF'!R22/100*'PROGRES BOBOT'!$J22 -> 1.8248778 | ... CX22: ='HARIAN KOMULATIF'!CX22/100*'PROGRES BOBOT'!$J22 -> 1.8248778
A23: 7 | B23: Pekerjaan urugan tanah peninggian lantai termasuk pemadatan tanah | F23: 256 | G23: m³ | H23: 65802 | I23: =H23*F23 -> 16845312 | J23: =I23/I$364*100 -> 1.6845273 | K23: ='HARIAN KOMULATIF'!K23/100*'PROGRES BOBOT'!$J23 -> 0 | L23: ='HARIAN KOMULATIF'!L23/100*'PROGRES BOBOT'!$J23 -> 0 | M23: ='HARIAN KOMULATIF'!M23/100*'PROGRES BOBOT'!$J23 -> 0 | N23: ='HARIAN KOMULATIF'!N23/100*'PROGRES BOBOT'!$J23 -> 0 | O23: ='HARIAN KOMULATIF'!O23/100*'PROGRES BOBOT'!$J23 -> 0 | P23: ='HARIAN KOMULATIF'!P23/100*'PROGRES BOBOT'!$J23 -> 0 | Q23: ='HARIAN KOMULATIF'!Q23/100*'PROGRES BOBOT'!$J23 -> 0 | R23: ='HARIAN KOMULATIF'!R23/100*'PROGRES BOBOT'!$J23 -> 0.84226366 | ... CX23: ='HARIAN KOMULATIF'!CX23/100*'PROGRES BOBOT'!$J23 -> 1.6845273
A24: 8 | B24: Pekerjaan pondasi footplat tipe F1a | K24: ='HARIAN KOMULATIF'!K24/100*'PROGRES BOBOT'!$J24 -> 0 | L24: ='HARIAN KOMULATIF'!L24/100*'PROGRES BOBOT'!$J24 -> 0 | M24: ='HARIAN KOMULATIF'!M24/100*'PROGRES BOBOT'!$J24 -> 0 | N24: ='HARIAN KOMULATIF'!N24/100*'PROGRES BOBOT'!$J24 -> 0 | O24: ='HARIAN KOMULATIF'!O24/100*'PROGRES BOBOT'!$J24 -> 0 | P24: ='HARIAN KOMULATIF'!P24/100*'PROGRES BOBOT'!$J24 -> 0 | Q24: ='HARIAN KOMULATIF'!Q24/100*'PROGRES BOBOT'!$J24 -> 0 | R24: ='HARIAN KOMULATIF'!R24/100*'PROGRES BOBOT'!$J24 -> 0 | ... CX24: ='HARIAN KOMULATIF'!CX24/100*'PROGRES BOBOT'!$J24 -> 0
B25: - Pekerjaan beton K-225 | F25: 5.76 | G25: m³ | H25: 772596 | I25: =H25*F25 -> 4450153 | J25: =I25/I$364*100 -> 0.44501427 | K25: ='HARIAN KOMULATIF'!K25/100*'PROGRES BOBOT'!$J25 -> 0 | L25: ='HARIAN KOMULATIF'!L25/100*'PROGRES BOBOT'!$J25 -> 0 | M25: ='HARIAN KOMULATIF'!M25/100*'PROGRES BOBOT'!$J25 -> 0 | N25: ='HARIAN KOMULATIF'!N25/100*'PROGRES BOBOT'!$J25 -> 0 | O25: ='HARIAN KOMULATIF'!O25/100*'PROGRES BOBOT'!$J25 -> 0 | P25: ='HARIAN KOMULATIF'!P25/100*'PROGRES BOBOT'!$J25 -> 0 | Q25: ='HARIAN KOMULATIF'!Q25/100*'PROGRES BOBOT'!$J25 -> 0 | R25: ='HARIAN KOMULATIF'!R25/100*'PROGRES BOBOT'!$J25 -> 0 | ... CX25: ='HARIAN KOMULATIF'!CX25/100*'PROGRES BOBOT'!$J25 -> 0
B26: - Pekerjaan bekisting pondasi | F26: 7 | G26: m² | H26: 87929.63 | I26: =H26*F26 -> 615507.41 | J26: =I26/I$364*100 -> 0.061550599 | K26: ='HARIAN KOMULATIF'!K26/100*'PROGRES BOBOT'!$J26 -> 0 | L26: ='HARIAN KOMULATIF'!L26/100*'PROGRES BOBOT'!$J26 -> 0 | M26: ='HARIAN KOMULATIF'!M26/100*'PROGRES BOBOT'!$J26 -> 0 | N26: ='HARIAN KOMULATIF'!N26/100*'PROGRES BOBOT'!$J26 -> 0 | O26: ='HARIAN KOMULATIF'!O26/100*'PROGRES BOBOT'!$J26 -> 0 | P26: ='HARIAN KOMULATIF'!P26/100*'PROGRES BOBOT'!$J26 -> 0 | Q26: ='HARIAN KOMULATIF'!Q26/100*'PROGRES BOBOT'!$J26 -> 0 | R26: ='HARIAN KOMULATIF'!R26/100*'PROGRES BOBOT'!$J26 -> 0 | ... CX26: ='HARIAN KOMULATIF'!CX26/100*'PROGRES BOBOT'!$J26 -> 0
B27: - Pekerjaan pembesian ulir | F27: 180.52116 | G27: kg | H27: 12818.52 | I27: =H27*F27 -> 2314014.1 | J27: =I27/I$364*100 -> 0.23140088 | K27: ='HARIAN KOMULATIF'!K27/100*'PROGRES BOBOT'!$J27 -> 0 | L27: ='HARIAN KOMULATIF'!L27/100*'PROGRES BOBOT'!$J27 -> 0 | M27: ='HARIAN KOMULATIF'!M27/100*'PROGRES BOBOT'!$J27 -> 0 | N27: ='HARIAN KOMULATIF'!N27/100*'PROGRES BOBOT'!$J27 -> 0 | O27: ='HARIAN KOMULATIF'!O27/100*'PROGRES BOBOT'!$J27 -> 0 | P27: ='HARIAN KOMULATIF'!P27/100*'PROGRES BOBOT'!$J27 -> 0 | Q27: ='HARIAN KOMULATIF'!Q27/100*'PROGRES BOBOT'!$J27 -> 0 | R27: ='HARIAN KOMULATIF'!R27/100*'PROGRES BOBOT'!$J27 -> 0 | ... CX27: ='HARIAN KOMULATIF'!CX27/100*'PROGRES BOBOT'!$J27 -> 0
B28: - Pekerjaan pembesian polos | F28: 90.016497 | G28: kg | H28: 11876.74 | I28: =H28*F28 -> 1069102.5 | J28: =I28/I$364*100 -> 0.10691001 | K28: ='HARIAN KOMULATIF'!K28/100*'PROGRES BOBOT'!$J28 -> 0 | L28: ='HARIAN KOMULATIF'!L28/100*'PROGRES BOBOT'!$J28 -> 0 | M28: ='HARIAN KOMULATIF'!M28/100*'PROGRES BOBOT'!$J28 -> 0 | N28: ='HARIAN KOMULATIF'!N28/100*'PROGRES BOBOT'!$J28 -> 0 | O28: ='HARIAN KOMULATIF'!O28/100*'PROGRES BOBOT'!$J28 -> 0 | P28: ='HARIAN KOMULATIF'!P28/100*'PROGRES BOBOT'!$J28 -> 0 | Q28: ='HARIAN KOMULATIF'!Q28/100*'PROGRES BOBOT'!$J28 -> 0 | R28: ='HARIAN KOMULATIF'!R28/100*'PROGRES BOBOT'!$J28 -> 0 | ... CX28: ='HARIAN KOMULATIF'!CX28/100*'PROGRES BOBOT'!$J28 -> 0
A29: 9 | B29: Pekerjaan pondasi footplat tipe F1b | K29: ='HARIAN KOMULATIF'!K29/100*'PROGRES BOBOT'!$J29 -> 0 | L29: ='HARIAN KOMULATIF'!L29/100*'PROGRES BOBOT'!$J29 -> 0 | M29: ='HARIAN KOMULATIF'!M29/100*'PROGRES BOBOT'!$J29 -> 0 | N29: ='HARIAN KOMULATIF'!N29/100*'PROGRES BOBOT'!$J29 -> 0 | O29: ='HARIAN KOMULATIF'!O29/100*'PROGRES BOBOT'!$J29 -> 0 | P29: ='HARIAN KOMULATIF'!P29/100*'PROGRES BOBOT'!$J29 -> 0 | Q29: ='HARIAN KOMULATIF'!Q29/100*'PROGRES BOBOT'!$J29 -> 0 | R29: ='HARIAN KOMULATIF'!R29/100*'PROGRES BOBOT'!$J29 -> 0 | ... CX29: ='HARIAN KOMULATIF'!CX29/100*'PROGRES BOBOT'!$J29 -> 0
B30: - Pekerjaan beton K-225 | F30: 4.55 | G30: m³ | H30: =H25 -> 772596 | I30: =H30*F30 -> 3515311.8 | J30: =I30/I$364*100 -> 0.35153037 | K30: ='HARIAN KOMULATIF'!K30/100*'PROGRES BOBOT'!$J30 -> 0 | L30: ='HARIAN KOMULATIF'!L30/100*'PROGRES BOBOT'!$J30 -> 0 | M30: ='HARIAN KOMULATIF'!M30/100*'PROGRES BOBOT'!$J30 -> 0 | N30: ='HARIAN KOMULATIF'!N30/100*'PROGRES BOBOT'!$J30 -> 0 | O30: ='HARIAN KOMULATIF'!O30/100*'PROGRES BOBOT'!$J30 -> 0 | P30: ='HARIAN KOMULATIF'!P30/100*'PROGRES BOBOT'!$J30 -> 0 | Q30: ='HARIAN KOMULATIF'!Q30/100*'PROGRES BOBOT'!$J30 -> 0 | R30: ='HARIAN KOMULATIF'!R30/100*'PROGRES BOBOT'!$J30 -> 0 | ... CX30: ='HARIAN KOMULATIF'!CX30/100*'PROGRES BOBOT'!$J30 -> 0
B31: - Pekerjaan bekisting pondasi | F31: 9 | G31: m² | H31: =H26 -> 87929.63 | I31: =H31*F31 -> 791366.67 | J31: =I31/I$364*100 -> 0.079136485 | K31: ='HARIAN KOMULATIF'!K31/100*'PROGRES BOBOT'!$J31 -> 0 | L31: ='HARIAN KOMULATIF'!L31/100*'PROGRES BOBOT'!$J31 -> 0 | M31: ='HARIAN KOMULATIF'!M31/100*'PROGRES BOBOT'!$J31 -> 0 | N31: ='HARIAN KOMULATIF'!N31/100*'PROGRES BOBOT'!$J31 -> 0 | O31: ='HARIAN KOMULATIF'!O31/100*'PROGRES BOBOT'!$J31 -> 0 | P31: ='HARIAN KOMULATIF'!P31/100*'PROGRES BOBOT'!$J31 -> 0 | Q31: ='HARIAN KOMULATIF'!Q31/100*'PROGRES BOBOT'!$J31 -> 0 | R31: ='HARIAN KOMULATIF'!R31/100*'PROGRES BOBOT'!$J31 -> 0 | ... CX31: ='HARIAN KOMULATIF'!CX31/100*'PROGRES BOBOT'!$J31 -> 0
B32: - Pekerjaan pembesian ulir | F32: 232.09864 | G32: kg | H32: =H27 -> 12818.52 | I32: =H32*F32 -> 2975161 | J32: =I32/I$364*100 -> 0.29751542 | K32: ='HARIAN KOMULATIF'!K32/100*'PROGRES BOBOT'!$J32 -> 0 | L32: ='HARIAN KOMULATIF'!L32/100*'PROGRES BOBOT'!$J32 -> 0 | M32: ='HARIAN KOMULATIF'!M32/100*'PROGRES BOBOT'!$J32 -> 0 | N32: ='HARIAN KOMULATIF'!N32/100*'PROGRES BOBOT'!$J32 -> 0 | O32: ='HARIAN KOMULATIF'!O32/100*'PROGRES BOBOT'!$J32 -> 0 | P32: ='HARIAN KOMULATIF'!P32/100*'PROGRES BOBOT'!$J32 -> 0 | Q32: ='HARIAN KOMULATIF'!Q32/100*'PROGRES BOBOT'!$J32 -> 0 | R32: ='HARIAN KOMULATIF'!R32/100*'PROGRES BOBOT'!$J32 -> 0 | ... CX32: ='HARIAN KOMULATIF'!CX32/100*'PROGRES BOBOT'!$J32 -> 0
B33: - Pekerjaan pembesian polos | F33: 121.03838 | G33: kg | H33: =H28 -> 11876.74 | I33: =H33*F33 -> 1437541.4 | J33: =I33/I$364*100 -> 0.14375381 | K33: ='HARIAN KOMULATIF'!K33/100*'PROGRES BOBOT'!$J33 -> 0 | L33: ='HARIAN KOMULATIF'!L33/100*'PROGRES BOBOT'!$J33 -> 0 | M33: ='HARIAN KOMULATIF'!M33/100*'PROGRES BOBOT'!$J33 -> 0 | N33: ='HARIAN KOMULATIF'!N33/100*'PROGRES BOBOT'!$J33 -> 0 | O33: ='HARIAN KOMULATIF'!O33/100*'PROGRES BOBOT'!$J33 -> 0 | P33: ='HARIAN KOMULATIF'!P33/100*'PROGRES BOBOT'!$J33 -> 0 | Q33: ='HARIAN KOMULATIF'!Q33/100*'PROGRES BOBOT'!$J33 -> 0 | R33: ='HARIAN KOMULATIF'!R33/100*'PROGRES BOBOT'!$J33 -> 0 | ... CX33: ='HARIAN KOMULATIF'!CX33/100*'PROGRES BOBOT'!$J33 -> 0
A34: 10 | B34: Pekerjaan pondasi footplat tipe F1c | K34: ='HARIAN KOMULATIF'!K34/100*'PROGRES BOBOT'!$J34 -> 0 | L34: ='HARIAN KOMULATIF'!L34/100*'PROGRES BOBOT'!$J34 -> 0 | M34: ='HARIAN KOMULATIF'!M34/100*'PROGRES BOBOT'!$J34 -> 0 | N34: ='HARIAN KOMULATIF'!N34/100*'PROGRES BOBOT'!$J34 -> 0 | O34: ='HARIAN KOMULATIF'!O34/100*'PROGRES BOBOT'!$J34 -> 0 | P34: ='HARIAN KOMULATIF'!P34/100*'PROGRES BOBOT'!$J34 -> 0 | Q34: ='HARIAN KOMULATIF'!Q34/100*'PROGRES BOBOT'!$J34 -> 0 | R34: ='HARIAN KOMULATIF'!R34/100*'PROGRES BOBOT'!$J34 -> 0 | ... CX34: ='HARIAN KOMULATIF'!CX34/100*'PROGRES BOBOT'!$J34 -> 0
B35: - Pekerjaan beton K-225 | F35: 0.78875 | G35: m³ | H35: =H30 -> 772596 | I35: =H35*F35 -> 609385.1 | J35: =I35/I$364*100 -> 0.060938369 | K35: ='HARIAN KOMULATIF'!K35/100*'PROGRES BOBOT'!$J35 -> 0 | L35: ='HARIAN KOMULATIF'!L35/100*'PROGRES BOBOT'!$J35 -> 0 | M35: ='HARIAN KOMULATIF'!M35/100*'PROGRES BOBOT'!$J35 -> 0 | N35: ='HARIAN KOMULATIF'!N35/100*'PROGRES BOBOT'!$J35 -> 0 | O35: ='HARIAN KOMULATIF'!O35/100*'PROGRES BOBOT'!$J35 -> 0 | P35: ='HARIAN KOMULATIF'!P35/100*'PROGRES BOBOT'!$J35 -> 0 | Q35: ='HARIAN KOMULATIF'!Q35/100*'PROGRES BOBOT'!$J35 -> 0 | R35: ='HARIAN KOMULATIF'!R35/100*'PROGRES BOBOT'!$J35 -> 0 | ... CX35: ='HARIAN KOMULATIF'!CX35/100*'PROGRES BOBOT'!$J35 -> 0
B36: - Pekerjaan bekisting pondasi | F36: 2 | G36: m² | H36: =H31 -> 87929.63 | I36: =H36*F36 -> 175859.26 | J36: =I36/I$364*100 -> 0.017585885 | K36: ='HARIAN KOMULATIF'!K36/100*'PROGRES BOBOT'!$J36 -> 0 | L36: ='HARIAN KOMULATIF'!L36/100*'PROGRES BOBOT'!$J36 -> 0 | M36: ='HARIAN KOMULATIF'!M36/100*'PROGRES BOBOT'!$J36 -> 0 | N36: ='HARIAN KOMULATIF'!N36/100*'PROGRES BOBOT'!$J36 -> 0 | O36: ='HARIAN KOMULATIF'!O36/100*'PROGRES BOBOT'!$J36 -> 0 | P36: ='HARIAN KOMULATIF'!P36/100*'PROGRES BOBOT'!$J36 -> 0 | Q36: ='HARIAN KOMULATIF'!Q36/100*'PROGRES BOBOT'!$J36 -> 0 | R36: ='HARIAN KOMULATIF'!R36/100*'PROGRES BOBOT'!$J36 -> 0 | ... CX36: ='HARIAN KOMULATIF'!CX36/100*'PROGRES BOBOT'!$J36 -> 0
B37: - Pekerjaan pembesian ulir | F37: 51.577475 | G37: kg | H37: =H32 -> 12818.52 | I37: =H37*F37 -> 661146.9 | J37: =I37/I$364*100 -> 0.066114537 | K37: ='HARIAN KOMULATIF'!K37/100*'PROGRES BOBOT'!$J37 -> 0 | L37: ='HARIAN KOMULATIF'!L37/100*'PROGRES BOBOT'!$J37 -> 0 | M37: ='HARIAN KOMULATIF'!M37/100*'PROGRES BOBOT'!$J37 -> 0 | N37: ='HARIAN KOMULATIF'!N37/100*'PROGRES BOBOT'!$J37 -> 0 | O37: ='HARIAN KOMULATIF'!O37/100*'PROGRES BOBOT'!$J37 -> 0 | P37: ='HARIAN KOMULATIF'!P37/100*'PROGRES BOBOT'!$J37 -> 0 | Q37: ='HARIAN KOMULATIF'!Q37/100*'PROGRES BOBOT'!$J37 -> 0 | R37: ='HARIAN KOMULATIF'!R37/100*'PROGRES BOBOT'!$J37 -> 0 | ... CX37: ='HARIAN KOMULATIF'!CX37/100*'PROGRES BOBOT'!$J37 -> 0
B38: - Pekerjaan pembesian polos | F38: 26.897418 | G38: kg | H38: =H33 -> 11876.74 | I38: =H38*F38 -> 319453.64 | J38: =I38/I$364*100 -> 0.031945291 | K38: ='HARIAN KOMULATIF'!K38/100*'PROGRES BOBOT'!$J38 -> 0 | L38: ='HARIAN KOMULATIF'!L38/100*'PROGRES BOBOT'!$J38 -> 0 | M38: ='HARIAN KOMULATIF'!M38/100*'PROGRES BOBOT'!$J38 -> 0 | N38: ='HARIAN KOMULATIF'!N38/100*'PROGRES BOBOT'!$J38 -> 0 | O38: ='HARIAN KOMULATIF'!O38/100*'PROGRES BOBOT'!$J38 -> 0 | P38: ='HARIAN KOMULATIF'!P38/100*'PROGRES BOBOT'!$J38 -> 0 | Q38: ='HARIAN KOMULATIF'!Q38/100*'PROGRES BOBOT'!$J38 -> 0 | R38: ='HARIAN KOMULATIF'!R38/100*'PROGRES BOBOT'!$J38 -> 0 | ... CX38: ='HARIAN KOMULATIF'!CX38/100*'PROGRES BOBOT'!$J38 -> 0
A39: 11 | B39: Pekerjaan pondasi footplat tipe F2 | K39: ='HARIAN KOMULATIF'!K39/100*'PROGRES BOBOT'!$J39 -> 0 | L39: ='HARIAN KOMULATIF'!L39/100*'PROGRES BOBOT'!$J39 -> 0 | M39: ='HARIAN KOMULATIF'!M39/100*'PROGRES BOBOT'!$J39 -> 0 | N39: ='HARIAN KOMULATIF'!N39/100*'PROGRES BOBOT'!$J39 -> 0 | O39: ='HARIAN KOMULATIF'!O39/100*'PROGRES BOBOT'!$J39 -> 0 | P39: ='HARIAN KOMULATIF'!P39/100*'PROGRES BOBOT'!$J39 -> 0 | Q39: ='HARIAN KOMULATIF'!Q39/100*'PROGRES BOBOT'!$J39 -> 0 | R39: ='HARIAN KOMULATIF'!R39/100*'PROGRES BOBOT'!$J39 -> 0 | ... CX39: ='HARIAN KOMULATIF'!CX39/100*'PROGRES BOBOT'!$J39 -> 0
B40: - Pekerjaan beton K-225 | F40: 1.512 | G40: m³ | H40: =H35 -> 772596 | I40: =H40*F40 -> 1168165.2 | J40: =I40/I$364*100 -> 0.11681625 | K40: ='HARIAN KOMULATIF'!K40/100*'PROGRES BOBOT'!$J40 -> 0 | L40: ='HARIAN KOMULATIF'!L40/100*'PROGRES BOBOT'!$J40 -> 0 | M40: ='HARIAN KOMULATIF'!M40/100*'PROGRES BOBOT'!$J40 -> 0 | N40: ='HARIAN KOMULATIF'!N40/100*'PROGRES BOBOT'!$J40 -> 0 | O40: ='HARIAN KOMULATIF'!O40/100*'PROGRES BOBOT'!$J40 -> 0 | P40: ='HARIAN KOMULATIF'!P40/100*'PROGRES BOBOT'!$J40 -> 0 | Q40: ='HARIAN KOMULATIF'!Q40/100*'PROGRES BOBOT'!$J40 -> 0 | R40: ='HARIAN KOMULATIF'!R40/100*'PROGRES BOBOT'!$J40 -> 0 | ... CX40: ='HARIAN KOMULATIF'!CX40/100*'PROGRES BOBOT'!$J40 -> 0
B41: - Pekerjaan bekisting pondasi | F41: 4.8 | G41: m² | H41: =H36 -> 87929.63 | I41: =H41*F41 -> 422062.22 | J41: =I41/I$364*100 -> 0.042206125 | K41: ='HARIAN KOMULATIF'!K41/100*'PROGRES BOBOT'!$J41 -> 0 | L41: ='HARIAN KOMULATIF'!L41/100*'PROGRES BOBOT'!$J41 -> 0 | M41: ='HARIAN KOMULATIF'!M41/100*'PROGRES BOBOT'!$J41 -> 0 | N41: ='HARIAN KOMULATIF'!N41/100*'PROGRES BOBOT'!$J41 -> 0 | O41: ='HARIAN KOMULATIF'!O41/100*'PROGRES BOBOT'!$J41 -> 0 | P41: ='HARIAN KOMULATIF'!P41/100*'PROGRES BOBOT'!$J41 -> 0 | Q41: ='HARIAN KOMULATIF'!Q41/100*'PROGRES BOBOT'!$J41 -> 0 | R41: ='HARIAN KOMULATIF'!R41/100*'PROGRES BOBOT'!$J41 -> 0 | ... CX41: ='HARIAN KOMULATIF'!CX41/100*'PROGRES BOBOT'!$J41 -> 0
B42: - Pekerjaan pembesian ulir | F42: 103.13828 | G42: kg | H42: =H37 -> 12818.52 | I42: =H42*F42 -> 1322080.1 | J42: =I42/I$364*100 -> 0.13220771 | K42: ='HARIAN KOMULATIF'!K42/100*'PROGRES BOBOT'!$J42 -> 0 | L42: ='HARIAN KOMULATIF'!L42/100*'PROGRES BOBOT'!$J42 -> 0 | M42: ='HARIAN KOMULATIF'!M42/100*'PROGRES BOBOT'!$J42 -> 0 | N42: ='HARIAN KOMULATIF'!N42/100*'PROGRES BOBOT'!$J42 -> 0 | O42: ='HARIAN KOMULATIF'!O42/100*'PROGRES BOBOT'!$J42 -> 0 | P42: ='HARIAN KOMULATIF'!P42/100*'PROGRES BOBOT'!$J42 -> 0 | Q42: ='HARIAN KOMULATIF'!Q42/100*'PROGRES BOBOT'!$J42 -> 0 | R42: ='HARIAN KOMULATIF'!R42/100*'PROGRES BOBOT'!$J42 -> 0 | ... CX42: ='HARIAN KOMULATIF'!CX42/100*'PROGRES BOBOT'!$J42 -> 0
B43: - Pekerjaan pembesian polos | F43: 51.835715 | G43: kg | H43: =H38 -> 11876.74 | I43: =H43*F43 -> 615639.3 | J43: =I43/I$364*100 -> 0.061563789 | K43: ='HARIAN KOMULATIF'!K43/100*'PROGRES BOBOT'!$J43 -> 0 | L43: ='HARIAN KOMULATIF'!L43/100*'PROGRES BOBOT'!$J43 -> 0 | M43: ='HARIAN KOMULATIF'!M43/100*'PROGRES BOBOT'!$J43 -> 0 | N43: ='HARIAN KOMULATIF'!N43/100*'PROGRES BOBOT'!$J43 -> 0 | O43: ='HARIAN KOMULATIF'!O43/100*'PROGRES BOBOT'!$J43 -> 0 | P43: ='HARIAN KOMULATIF'!P43/100*'PROGRES BOBOT'!$J43 -> 0 | Q43: ='HARIAN KOMULATIF'!Q43/100*'PROGRES BOBOT'!$J43 -> 0 | R43: ='HARIAN KOMULATIF'!R43/100*'PROGRES BOBOT'!$J43 -> 0 | ... CX43: ='HARIAN KOMULATIF'!CX43/100*'PROGRES BOBOT'!$J43 -> 0
...

Sheet GRAFIK S
A1: GRAFIK "S" HARIAN
A3: PEKERJAAN | D3: : PEMBANGUNAN KOPERASI MERAH PUTIH PT. AGRINAS PANGAN NUSANTARA (PERSERO)
A4: LOKASI | D4: : PROVINSI JAWA TENGAH
A5: TAHUN ANGGARAN | D5: : 2025
A7: NO | B7: URAIAN PEKERJAAN | F7: VOLUME | G7: SATUAN | H7: HARGA SATUAN | I7: JUMLAH HARGA SATUAN | J7: NILAI BOBOT (%) | K7: NOVEMBER | AO7: DESEMBER | BT7: JANUARI
K8: SAB | L8: MING | M8: SEN | N8: SEL | O8: RAB | P8: KAM | Q8: JUM | R8: SAB | S8: MING | T8: SEN | U8: SEL | V8: RAB | W8: KAM | X8: JUM | Y8: SAB | Z8: MING | AA8: SEN | AB8: SEL | AC8: RAB | AD8: KAM | AE8: JUM | AF8: SAB | AG8: MING | AH8: SEN | AI8: SEL | AJ8: RAB | AK8: KAM | AL8: JUM | AM8: SAB | AN8: MING | AO8: SEN | AP8: SEL | AQ8: RAB | AR8: KAM | AS8: JUM | AT8: SAB | AU8: MING | AV8: SEN | AW8: SEL | AX8: RAB | AY8: KAM | AZ8: JUM | BA8: SAB | BB8: MING | BC8: SEN | BD8: SEL | BE8: RAB | BF8: KAM | BG8: JUM | BH8: SAB | BI8: MING | BJ8: SEN | BK8: SEL | BL8: RAB | BM8: KAM | BN8: JUM | BO8: SAB | BP8: MING | BQ8: SEN | BR8: SEL | BS8: RAB | BT8: KAM | BU8: JUM | BV8: SAB | BW8: MING | BX8: SEN | BY8: SEL | BZ8: RAB | CA8: KAM | CB8: JUM | CC8: SAB | CD8: MING | CE8: SEN | CF8: SEL | CG8: RAB | CH8: KAM | CI8: JUM | CJ8: SAB | CK8: MING | CL8: SEN | CM8: SEL | CN8: RAB | CO8: KAM | CP8: JUM | CQ8: SAB | CR8: MING | CS8: SEN | CT8: SEL | CU8: RAB | CV8: KAM | CW8: JUM | CX8: SAB
H9: (Rp) | I9: (Rp) | K9: 1 | L9: 2 | M9: 3 | N9: 4 | O9: 5 | P9: 6 | Q9: 7 | R9: 8 | S9: 9 | T9: 10 | U9: 11 | V9: 12 | W9: 13 | X9: 14 | Y9: 15 | Z9: 16 | AA9: 17 | AB9: 18 | AC9: 19 | AD9: 20 | AE9: 21 | AF9: 22 | AG9: 23 | AH9: 24 | AI9: 25 | AJ9: 26 | AK9: 27 | AL9: 28 | AM9: 29 | AN9: 30 | AO9: 1 | AP9: 2 | AQ9: 3 | AR9: 4 | AS9: 5 | AT9: 6 | AU9: 7 | AV9: 8 | AW9: 9 | AX9: 10 | AY9: 11 | AZ9: 12 | BA9: 13 | BB9: 14 | BC9: 15 | BD9: 16 | BE9: 17 | BF9: 18 | BG9: 19 | BH9: 20 | BI9: 21 | BJ9: 22 | BK9: 23 | BL9: 24 | BM9: 25 | BN9: 26 | BO9: 27 | BP9: 28 | BQ9: 29 | BR9: 30 | BS9: 31 | BT9: 1 | BU9: 2 | BV9: 3 | BW9: 4 | BX9: 5 | BY9: 6 | BZ9: 7 | CA9: 8 | CB9: 9 | CC9: 10 | CD9: 11 | CE9: 12 | CF9: 13 | CG9: 14 | CH9: 15 | CI9: 16 | CJ9: 17 | CK9: 18 | CL9: 19 | CM9: 20 | CN9: 21 | CO9: 22 | CP9: 23 | CQ9: 24 | CR9: 25 | CS9: 26 | CT9: 27 | CU9: 28 | CV9: 29 | CW9: 30 | CX9: 31
A11: I | B11: PEKERJAAN PERSIAPAN | I11: =SUM(I12:I13) -> 21788295 | J11: =SUM(J12:J13) -> 2.1788245 | K11: =J11/4 -> 0.54470612 | L11: =K11 -> 0.54470612 | M11: =L11 -> 0.54470612 | N11: =M11 -> 0.54470612 | CY11: 100
A12: 1 | B12: Pengukuran dan pasang bouwplank | F12: 60.3 | G12: m' | H12: 78900 | I12: =H12*F12 -> 4757670 | J12: =I12/I$374*100 -> 0.4757659 | K12: 10 | L12: 60 | M12: 10 | N12: 20
A13: 2 | B13: Pembersihan lahan awal sampai akhir pekerjaan | F13: 908.3 | G13: m² | H13: 18750 | I13: =H13*F13 -> 17030625 | J13: =I13/I$374*100 -> 1.7030586 | K13: 25 | L13: 50
A18: II | B18: PEKERJAAN STRUKTUR | J18: =SUM(J20:J213) -> 51.056568 | O18: =J18/50 -> 1.0211314 | P18: =O18 -> 1.0211314 | Q18: =P18 -> 1.0211314 | R18: =Q18 -> 1.0211314 | S18: =R18 -> 1.0211314 | T18: =S18 -> 1.0211314 | U18: =T18 -> 1.0211314 | V18: =U18 -> 1.0211314 | W18: =V18 -> 1.0211314 | ... BL18: =BK18 -> 1.0211314
B19: II.1 Pekerjaan Struktur Bawah | I19: =SUM(I20:I68) -> 1.6194539e+08
A20: 1 | B20: Pekerjaan galian tanah pondasi footplat | F20: 70.78 | G20: m³ | H20: 70180 | I20: =H20*F20 -> 4967340.4 | J20: =I20/I$374*100 -> 0.49673289
A21: 2 | B21: Pekerjaan urugan tanah kembali pondasi footplat | F21: 18.594 | G21: m³ | H21: 46750 | I21: =H21*F21 -> 869269.5 | J21: =I21/I$374*100 -> 0.08692675
A22: 3 | B22: Pekerjaan lantai kerja bawah pondasi footplat | F22: 2.32425 | G22: m³ | H22: 735328 | I22: =H22*F22 -> 1709086.1 | J22: =I22/I$374*100 -> 0.17090822
A23: 4 | B23: Pekerjaan galian tanah pondasi batu belah | F23: 19.8 | G23: m³ | H23: 70180 | I23: =H23*F23 -> 1389564 | J23: =I23/I$374*100 -> 0.13895608
A24: 5 | B24: Pekerjaan lantai kerja bawah pondasi batu belah | F24: 4.65 | G24: m³ | H24: 735328 | I24: =H24*F24 -> 3419275.2 | J24: =I24/I$374*100 -> 0.34192673
A25: 6 | B25: Pekerjaan pondasi batu belah | F25: 27.9 | G25: m³ | H25: 654079.58 | I25: =H25*F25 -> 18248820 | J25: =I25/I$374*100 -> 1.8248778
A26: 7 | B26: Pekerjaan urugan tanah peninggian lantai termasuk pemadatan tanah | F26: 256 | G26: m³ | H26: 65802 | I26: =H26*F26 -> 16845312 | J26: =I26/I$374*100 -> 1.6845273
A27: 8 | B27: Pekerjaan pondasi footplat tipe F1a
B28: - Pekerjaan beton K-225 | F28: 5.76 | G28: m³ | H28: 772596 | I28: =H28*F28 -> 4450153 | J28: =I28/I$374*100 -> 0.44501427
B29: - Pekerjaan bekisting pondasi | F29: 7 | G29: m² | H29: 87929.63 | I29: =H29*F29 -> 615507.41 | J29: =I29/I$374*100 -> 0.061550599
B30: - Pekerjaan pembesian ulir | F30: 180.52116 | G30: kg | H30: 12818.52 | I30: =H30*F30 -> 2314014.1 | J30: =I30/I$374*100 -> 0.23140088
B31: - Pekerjaan pembesian polos | F31: 90.016497 | G31: kg | H31: 11876.74 | I31: =H31*F31 -> 1069102.5 | J31: =I31/I$374*100 -> 0.10691001
A32: 9 | B32: Pekerjaan pondasi footplat tipe F1b
B33: - Pekerjaan beton K-225 | F33: 4.55 | G33: m³ | H33: =H28 -> 772596 | I33: =H33*F33 -> 3515311.8 | J33: =I33/I$374*100 -> 0.35153037
B34: - Pekerjaan bekisting pondasi | F34: 9 | G34: m² | H34: =H29 -> 87929.63 | I34: =H34*F34 -> 791366.67 | J34: =I34/I$374*100 -> 0.079136485
B35: - Pekerjaan pembesian ulir | F35: 232.09864 | G35: kg | H35: =H30 -> 12818.52 | I35: =H35*F35 -> 2975161 | J35: =I35/I$374*100 -> 0.29751542
B36: - Pekerjaan pembesian polos | F36: 121.03838 | G36: kg | H36: =H31 -> 11876.74 | I36: =H36*F36 -> 1437541.4 | J36: =I36/I$374*100 -> 0.14375381
A37: 10 | B37: Pekerjaan pondasi footplat tipe F1c
B38: - Pekerjaan beton K-225 | F38: 0.78875 | G38: m³ | H38: =H33 -> 772596 | I38: =H38*F38 -> 609385.1 | J38: =I38/I$374*100 -> 0.060938369
B39: - Pekerjaan bekisting pondasi | F39: 2 | G39: m² | H39: =H34 -> 87929.63 | I39: =H39*F39 -> 175859.26 | J39: =I39/I$374*100 -> 0.017585885
B40: - Pekerjaan pembesian ulir | F40: 51.577475 | G40: kg | H40: =H35 -> 12818.52 | I40: =H40*F40 -> 661146.9 | J40: =I40/I$374*100 -> 0.066114537
B41: - Pekerjaan pembesian polos | F41: 26.897418 | G41: kg | H41: =H36 -> 11876.74 | I41: =H41*F41 -> 319453.64 | J41: =I41/I$374*100 -> 0.031945291
A42: 11 | B42: Pekerjaan pondasi footplat tipe F2
B43: - Pekerjaan beton K-225 | F43: 1.512 | G43: m³ | H43: =H38 -> 772596 | I43: =H43*F43 -> 1168165.2 | J43: =I43/I$374*100 -> 0.11681625
B44: - Pekerjaan bekisting pondasi | F44: 4.8 | G44: m² | H44: =H39 -> 87929.63 | I44: =H44*F44 -> 422062.22 | J44: =I44/I$374*100 -> 0.042206125
B45: - Pekerjaan pembesian ulir | F45: 103.13828 | G45: kg | H45: =H40 -> 12818.52 | I45: =H45*F45 -> 1322080.1 | J45: =I45/I$374*100 -> 0.13220771
B46: - Pekerjaan pembesian polos | F46: 51.835715 | G46: kg | H46: =H41 -> 11876.74 | I46: =H46*F46 -> 615639.3 | J46: =I46/I$374*100 -> 0.061563789
A47: 12 | B47: Pekerjaan kolom pedestal tipe K1a ukuran 25 x 30 cm
...
